Workbook

Sheet INÍCIO
B2: SISTEMA DE VENDAS & DASHBOARD GERENCIAL
B3: Painel Executivo de Vendas, Indicadores de Desempenho (KPIs) e Controle de Acesso
B5: SISTEMA ONLINE | OPERADOR ATIVO: ADMINISTRADOR (ADMIN)
B10: ?? FILTRO ATIVO: Período: [ Este Mês (outubro/2026) ] | Operador: [ Vitória ] | Pedidos no Filtro: [ 2 pedidos ]
B11: FATURAMENTO TOTAL | D11: VENDAS CONCLUÍDAS | G11: TICKET MÉDIO | I11: LÍQUIDO A RECEBER
B12: 706.83 | D12: 2 ped. (4 itens) | G12: 353.415 | I12: 689.33
B15: 🏆 TOP 5 MELHORES CLIENTES (VOLUME COMPRADO) | G15: ?? TOP 5 PRODUTOS & SERVIÇOS MAIS VENDIDOS
B16: Pos | C16: Cliente | D16: Vendas | E16: Total Gasto (R$) | G16: Pos | H16: Produto / Serviço | I16: Qtd | J16: Faturamento
B17: 1º | C17: Carlos Alberto da Silva | D17: 1 | E17: 500 | G17: 1º | H17: Teclado Mecânico ABNT2 | I17: 1 | J17: 350 | L17: Teclado Mecânico ABNT2 | M17: 350
B18: 2º | C18: Beatriz Souza Almeida | D18: 1 | E18: 206.83 | G18: 2º | H18: Mouse Gamer RGB | I18: 1 | J18: 150 | L18: Mouse Gamer RGB | M18: 150
B19: 3º | C19: - | D19: 0 | E19: 0 | G19: 3º | H19: Bola de pilates ventilado azul | I19: 1 | J19: 134.38 | L19: Bola de pilates ventilado azul | M19: 134.38
B20: 4º | C20: - | D20: 0 | E20: 0 | G20: 4º | H20: Bola de vôlei profissional verde | I20: 1 | J20: 72.45 | L20: Bola de vôlei profissional verde | M20: 72.45
B21: 5º | C21: - | D21: 0 | E21: 0 | G21: 5º | H21: - | I21: 0 | J21: 0 | L21: - | M21: 0
B23: 💳 FATURAMENTO POR FORMA DE PAGAMENTO
B24: Dinheiro | D24: 0
B25: PIX | D25: 206.83
B26: Cartão de Crédito | D26: 500
B27: Cartão de Débito | D27: 0
B28: Boleto Bancário | D28: 0
B30: Última atualização: 19/10/2026 19:14:52 | ?? Segurança Ativa: Acessos protegidos

Sheet APURACAO_RESULTADOS
B2: 📊 APURAÇÃO MENSAL DE RESULTADOS (DRE - DEMONSTRATIVO DO EXERCÍCIO)
B5: EMPRESA: | C5: =CONFIG!B2 | D5: ANO: | E5: 2026
B7: 💰 VENDAS BRUTAS (ANO) | D7: 📈 VENDAS LÍQUIDAS (ANO) | G7: 🏷️ LUCRO BRUTO (APÓS CMV) | J7: 💸 DESPESAS & CUSTOS | M7: 🏆 RESULTADO LÍQUIDO | P7: 📊 LUCRATIVIDADE (%)
B8: =P12 | D8: =P19 | G8: =P23 | J8: =P15+P20+P24+P30+P37+P46 | M8: =P49 | P8: =IFERROR(P49/P19,0)
B11: ITEM | C11: ESTRUTURA DE CONTAS (APURAÇÃO DE RESULTADOS) | D11: JAN | E11: FEV | F11: MAR | G11: ABR | H11: MAI | I11: JUN | J11: JUL | K11: AGO | L11: SET | M11: OUT | N11: NOV | O11: DEZ | P11: TOTAL ANUAL | Q11: A.V. (%)
B12: 1 | C12: VENDAS BRUTAS | D12: =SUM(D13:D14) | E12: =SUM(E13:E14) | F12: =SUM(F13:F14) | G12: =SUM(G13:G14) | H12: =SUM(H13:H14) | I12: =SUM(I13:I14) | J12: =SUM(J13:J14) | K12: =SUM(K13:K14) | ... O12: =SUM(O13:O14) | P12: =SUM(D12:O12) | Q12: =IFERROR(P12/$P$19, 0)
B13: 1.1 | C13: Vendas de produtos | D13: 0 | E13: 0 | F13: 0 | G13: 0 | H13: 0 | I13: 0 | J13: 0 | K13: 0 | L13: 0 | M13: 5234.8 | N13: 0 | O13: 0 | P13: =SUM(D13:O13) | Q13: =IFERROR(P13/$P$19, 0)
B14: 1.2 | C14: Prestação de serviços | D14: 0 | E14: 0 | F14: 0 | G14: 0 | H14: 0 | I14: 0 | J14: 0 | K14: 0 | L14: 0 | M14: 0 | N14: 0 | O14: 0 | P14: =SUM(D14:O14) | Q14: =IFERROR(P14/$P$19, 0)
B15: 2 | C15: (-) Deduções da Receita Bruta | D15: =SUM(D16:D18) | E15: =SUM(E16:E18) | F15: =SUM(F16:F18) | G15: =SUM(G16:G18) | H15: =SUM(H16:H18) | I15: =SUM(I16:I18) | J15: =SUM(J16:J18) | K15: =SUM(K16:K18) | ... O15: =SUM(O16:O18) | P15: =SUM(D15:O15) | Q15: =IFERROR(P15/$P$19, 0)
B16: 2.1 | C16: (-) Devoluções | D16: =SUMIFS(DESPESAS!$H:$H, DESPESAS!$E:$E, "2.1 (-) Devoluções", DESPESAS!$L:$L, 1, DESPESAS!$M:$M, $E$5, DESPESAS!$J:$J, "<>Cancelada") | E16: =SUMIFS(DESPESAS!$H:$H, DESPESAS!$E:$E, "2.1 (-) Devoluções", DESPESAS!$L:$L, 2, DESPESAS!$M:$M, $E$5, DESPESAS!$J:$J, "<>Cancelada") | F16: =SUMIFS(DESPESAS!$H:$H, DESPESAS!$E:$E, "2.1 (-) Devoluções", DESPESAS!$L:$L, 3, DESPESAS!$M:$M, $E$5, DESPESAS!$J:$J, "<>Cancelada") | G16: =SUMIFS(DESPESAS!$H:$H, DESPESAS!$E:$E, "2.1 (-) Devoluções", DESPESAS!$L:$L, 4, DESPESAS!$M:$M, $E$5, DESPESAS!$J:$J, "<>Cancelada") | H16: =SUMIFS(DESPESAS!$H:$H, DESPESAS!$E:$E, "2.1 (-) Devoluções", DESPESAS!$L:$L, 5, DESPESAS!$M:$M, $E$5, DESPESAS!$J:$J, "<>Cancelada") | I16: =SUMIFS(DESPESAS!$H:$H, DESPESAS!$E:$E, "2.1 (-) Devoluções", DESPESAS!$L:$L, 6, DESPESAS!$M:$M, $E$5, DESPESAS!$J:$J, "<>Cancelada") | J16: =SUMIFS(DESPESAS!$H:$H, DESPESAS!$E:$E, "2.1 (-) Devoluções", DESPESAS!$L:$L, 7, DESPESAS!$M:$M, $E$5, DESPESAS!$J:$J, "<>Cancelada") | K16: =SUMIFS(DESPESAS!$H:$H, DESPESAS!$E:$E, "2.1 (-) Devoluções", DESPESAS!$L:$L, 8, DESPESAS!$M:$M, $E$5, DESPESAS!$J:$J, "<>Cancelada") | L16: =SUMIFS(DESPESAS!$H:$H, DESPESAS!$E:$E, "2.1 (-) Devoluções", DESPESAS!$L:$L, 9, DESPESAS!$M:$M, $E$5, DESPESAS!$J:$J, "<>Cancelada") | M16: =SUMIFS(DESPESAS!$H:$H, DESPESAS!$E:$E, "2.1 (-) Devoluções", DESPESAS!$L:$L, 10, DESPESAS!$M:$M, $E$5, DESPESAS!$J:$J, "<>Cancelada") | N16: =SUMIFS(DESPESAS!$H:$H, DESPESAS!$E:$E, "2.1 (-) Devoluções", DESPESAS!$L:$L, 11, DESPESAS!$M:$M, $E$5, DESPESAS!$J:$J, "<>Cancelada") | O16: =SUMIFS(DESPESAS!$H:$H, DESPESAS!$E:$E, "2.1 (-) Devoluções", DESPESAS!$L:$L, 12, DESPESAS!$M:$M, $E$5, DESPESAS!$J:$J, "<>Cancelada") | P16: =SUM(D16:O16) | Q16: =IFERROR(P16/$P$19, 0)
B17: 2.2 | C17: (-) Impostos e Contribuições sobre vendas | D17: =SUMIFS(DESPESAS!$H:$H, DESPESAS!$E:$E, "2.2 (-) Impostos e Contribuições sobre vendas", DESPESAS!$L:$L, 1, DESPESAS!$M:$M, $E$5, DESPESAS!$J:$J, "<>Cancelada") | E17: =SUMIFS(DESPESAS!$H:$H, DESPESAS!$E:$E, "2.2 (-) Impostos e Contribuições sobre vendas", DESPESAS!$L:$L, 2, DESPESAS!$M:$M, $E$5, DESPESAS!$J:$J, "<>Cancelada") | F17: =SUMIFS(DESPESAS!$H:$H, DESPESAS!$E:$E, "2.2 (-) Impostos e Contribuições sobre vendas", DESPESAS!$L:$L, 3, DESPESAS!$M:$M, $E$5, DESPESAS!$J:$J, "<>Cancelada") | G17: =SUMIFS(DESPESAS!$H:$H, DESPESAS!$E:$E, "2.2 (-) Impostos e Contribuições sobre vendas", DESPESAS!$L:$L, 4, DESPESAS!$M:$M, $E$5, DESPESAS!$J:$J, "<>Cancelada") | H17: =SUMIFS(DESPESAS!$H:$H, DESPESAS!$E:$E, "2.2 (-) Impostos e Contribuições sobre vendas", DESPESAS!$L:$L, 5, DESPESAS!$M:$M, $E$5, DESPESAS!$J:$J, "<>Cancelada") | I17: =SUMIFS(DESPESAS!$H:$H, DESPESAS!$E:$E, "2.2 (-) Impostos e Contribuições sobre vendas", DESPESAS!$L:$L, 6, DESPESAS!$M:$M, $E$5, DESPESAS!$J:$J, "<>Cancelada") | J17: =SUMIFS(DESPESAS!$H:$H, DESPESAS!$E:$E, "2.2 (-) Impostos e Contribuições sobre vendas", DESPESAS!$L:$L, 7, DESPESAS!$M:$M, $E$5, DESPESAS!$J:$J, "<>Cancelada") | K17: =SUMIFS(DESPESAS!$H:$H, DESPESAS!$E:$E, "2.2 (-) Impostos e Contribuições sobre vendas", DESPESAS!$L:$L, 8, DESPESAS!$M:$M, $E$5, DESPESAS!$J:$J, "<>Cancelada") | L17: =SUMIFS(DESPESAS!$H:$H, DESPESAS!$E:$E, "2.2 (-) Impostos e Contribuições sobre vendas", DESPESAS!$L:$L, 9, DESPESAS!$M:$M, $E$5, DESPESAS!$J:$J, "<>Cancelada") | M17: =SUMIFS(DESPESAS!$H:$H, DESPESAS!$E:$E, "2.2 (-) Impostos e Contribuições sobre vendas", DESPESAS!$L:$L, 10, DESPESAS!$M:$M, $E$5, DESPESAS!$J:$J, "<>Cancelada") | N17: =SUMIFS(DESPESAS!$H:$H, DESPESAS!$E:$E, "2.2 (-) Impostos e Contribuições sobre vendas", DESPESAS!$L:$L, 11, DESPESAS!$M:$M, $E$5, DESPESAS!$J:$J, "<>Cancelada") | O17: =SUMIFS(DESPESAS!$H:$H, DESPESAS!$E:$E, "2.2 (-) Impostos e Contribuições sobre vendas", DESPESAS!$L:$L, 12, DESPESAS!$M:$M, $E$5, DESPESAS!$J:$J, "<>Cancelada") | P17: =SUM(D17:O17) | Q17: =IFERROR(P17/$P$19, 0)
B18: 2.3 | C18: (-) Abatimentos e Descontos Concedidos | D18: 0 | E18: 0 | F18: 0 | G18: 0 | H18: 0 | I18: 0 | J18: 0 | K18: 0 | L18: 0 | M18: 350 | N18: 0 | O18: 0 | P18: =SUM(D18:O18) | Q18: =IFERROR(P18/$P$19, 0)
B19: 3 | C19: Vendas Líquidas (1 - 2) | D19: =D12-D15 | E19: =E12-E15 | F19: =F12-F15 | G19: =G12-G15 | H19: =H12-H15 | I19: =I12-I15 | J19: =J12-J15 | K19: =K12-K15 | ... O19: =O12-O15 | P19: =SUM(D19:O19) | Q19: =IFERROR(P19/$P$19, 0)
B20: 4 | C20: Custos das Vendas (CMV / CSP) | D20: =SUM(D21:D22) | E20: =SUM(E21:E22) | F20: =SUM(F21:F22) | G20: =SUM(G21:G22) | H20: =SUM(H21:H22) | I20: =SUM(I21:I22) | J20: =SUM(J21:J22) | K20: =SUM(K21:K22) | ... O20: =SUM(O21:O22) | P20: =SUM(D20:O20) | Q20: =IFERROR(P20/$P$19, 0)
B21: 4.1 | C21: (-) Custo das Mercadorias Vendidas | D21: =0+SUMIFS(DESPESAS!$H:$H,DESPESAS!$E:$E,"4.1 (-) Custo das Mercadorias Vendidas",DESPESAS!$L:$L,1,DESPESAS!$M:$M,$E$5,DESPESAS!$J:$J,"<>Cancelada") | E21: =0+SUMIFS(DESPESAS!$H:$H,DESPESAS!$E:$E,"4.1 (-) Custo das Mercadorias Vendidas",DESPESAS!$L:$L,2,DESPESAS!$M:$M,$E$5,DESPESAS!$J:$J,"<>Cancelada") | F21: =0+SUMIFS(DESPESAS!$H:$H,DESPESAS!$E:$E,"4.1 (-) Custo das Mercadorias Vendidas",DESPESAS!$L:$L,3,DESPESAS!$M:$M,$E$5,DESPESAS!$J:$J,"<>Cancelada") | G21: =0+SUMIFS(DESPESAS!$H:$H,DESPESAS!$E:$E,"4.1 (-) Custo das Mercadorias Vendidas",DESPESAS!$L:$L,4,DESPESAS!$M:$M,$E$5,DESPESAS!$J:$J,"<>Cancelada") | H21: =0+SUMIFS(DESPESAS!$H:$H,DESPESAS!$E:$E,"4.1 (-) Custo das Mercadorias Vendidas",DESPESAS!$L:$L,5,DESPESAS!$M:$M,$E$5,DESPESAS!$J:$J,"<>Cancelada") | I21: =0+SUMIFS(DESPESAS!$H:$H,DESPESAS!$E:$E,"4.1 (-) Custo das Mercadorias Vendidas",DESPESAS!$L:$L,6,DESPESAS!$M:$M,$E$5,DESPESAS!$J:$J,"<>Cancelada") | J21: =0+SUMIFS(DESPESAS!$H:$H,DESPESAS!$E:$E,"4.1 (-) Custo das Mercadorias Vendidas",DESPESAS!$L:$L,7,DESPESAS!$M:$M,$E$5,DESPESAS!$J:$J,"<>Cancelada") | K21: =0+SUMIFS(DESPESAS!$H:$H,DESPESAS!$E:$E,"4.1 (-) Custo das Mercadorias Vendidas",DESPESAS!$L:$L,8,DESPESAS!$M:$M,$E$5,DESPESAS!$J:$J,"<>Cancelada") | L21: =0+SUMIFS(DESPESAS!$H:$H,DESPESAS!$E:$E,"4.1 (-) Custo das Mercadorias Vendidas",DESPESAS!$L:$L,9,DESPESAS!$M:$M,$E$5,DESPESAS!$J:$J,"<>Cancelada") | M21: =2674.86+SUMIFS(DESPESAS!$H:$H,DESPESAS!$E:$E,"4.1 (-) Custo das Mercadorias Vendidas",DESPESAS!$L:$L,10,DESPESAS!$M:$M,$E$5,DESPESAS!$J:$J,"<>Cancelada") | N21: =0+SUMIFS(DESPESAS!$H:$H,DESPESAS!$E:$E,"4.1 (-) Custo das Mercadorias Vendidas",DESPESAS!$L:$L,11,DESPESAS!$M:$M,$E$5,DESPESAS!$J:$J,"<>Cancelada") | O21: =0+SUMIFS(DESPESAS!$H:$H,DESPESAS!$E:$E,"4.1 (-) Custo das Mercadorias Vendidas",DESPESAS!$L:$L,12,DESPESAS!$M:$M,$E$5,DESPESAS!$J:$J,"<>Cancelada") | P21: =SUM(D21:O21) | Q21: =IFERROR(P21/$P$19, 0)
B22: 4.2 | C22: (-) Custo dos Serviços Prestados | D22: =0+SUMIFS(DESPESAS!$H:$H,DESPESAS!$E:$E,"4.2 (-) Custo dos Serviços Prestados",DESPESAS!$L:$L,1,DESPESAS!$M:$M,$E$5,DESPESAS!$J:$J,"<>Cancelada") | E22: =0+SUMIFS(DESPESAS!$H:$H,DESPESAS!$E:$E,"4.2 (-) Custo dos Serviços Prestados",DESPESAS!$L:$L,2,DESPESAS!$M:$M,$E$5,DESPESAS!$J:$J,"<>Cancelada") | F22: =0+SUMIFS(DESPESAS!$H:$H,DESPESAS!$E:$E,"4.2 (-) Custo dos Serviços Prestados",DESPESAS!$L:$L,3,DESPESAS!$M:$M,$E$5,DESPESAS!$J:$J,"<>Cancelada") | G22: =0+SUMIFS(DESPESAS!$H:$H,DESPESAS!$E:$E,"4.2 (-) Custo dos Serviços Prestados",DESPESAS!$L:$L,4,DESPESAS!$M:$M,$E$5,DESPESAS!$J:$J,"<>Cancelada") | H22: =0+SUMIFS(DESPESAS!$H:$H,DESPESAS!$E:$E,"4.2 (-) Custo dos Serviços Prestados",DESPESAS!$L:$L,5,DESPESAS!$M:$M,$E$5,DESPESAS!$J:$J,"<>Cancelada") | I22: =0+SUMIFS(DESPESAS!$H:$H,DESPESAS!$E:$E,"4.2 (-) Custo dos Serviços Prestados",DESPESAS!$L:$L,6,DESPESAS!$M:$M,$E$5,DESPESAS!$J:$J,"<>Cancelada") | J22: =0+SUMIFS(DESPESAS!$H:$H,DESPESAS!$E:$E,"4.2 (-) Custo dos Serviços Prestados",DESPESAS!$L:$L,7,DESPESAS!$M:$M,$E$5,DESPESAS!$J:$J,"<>Cancelada") | K22: =0+SUMIFS(DESPESAS!$H:$H,DESPESAS!$E:$E,"4.2 (-) Custo dos Serviços Prestados",DESPESAS!$L:$L,8,DESPESAS!$M:$M,$E$5,DESPESAS!$J:$J,"<>Cancelada") | L22: =0+SUMIFS(DESPESAS!$H:$H,DESPESAS!$E:$E,"4.2 (-) Custo dos Serviços Prestados",DESPESAS!$L:$L,9,DESPESAS!$M:$M,$E$5,DESPESAS!$J:$J,"<>Cancelada") | M22: =0+SUMIFS(DESPESAS!$H:$H,DESPESAS!$E:$E,"4.2 (-) Custo dos Serviços Prestados",DESPESAS!$L:$L,10,DESPESAS!$M:$M,$E$5,DESPESAS!$J:$J,"<>Cancelada") | N22: =0+SUMIFS(DESPESAS!$H:$H,DESPESAS!$E:$E,"4.2 (-) Custo dos Serviços Prestados",DESPESAS!$L:$L,11,DESPESAS!$M:$M,$E$5,DESPESAS!$J:$J,"<>Cancelada") | O22: =0+SUMIFS(DESPESAS!$H:$H,DESPESAS!$E:$E,"4.2 (-) Custo dos Serviços Prestados",DESPESAS!$L:$L,12,DESPESAS!$M:$M,$E$5,DESPESAS!$J:$J,"<>Cancelada") | P22: =SUM(D22:O22) | Q22: =IFERROR(P22/$P$19, 0)
B23: 5 | C23: Resultado Operacional Bruto (3 - 4) | D23: =D19-D20 | E23: =E19-E20 | F23: =F19-F20 | G23: =G19-G20 | H23: =H19-H20 | I23: =I19-I20 | J23: =J19-J20 | K23: =K19-K20 | ... O23: =O19-O20 | P23: =SUM(D23:O23) | Q23: =IFERROR(P23/$P$19, 0)
B24: 6 | C24: Despesas Operacionais | D24: =SUM(D25:D26) | E24: =SUM(E25:E26) | F24: =SUM(F25:F26) | G24: =SUM(G25:G26) | H24: =SUM(H25:H26) | I24: =SUM(I25:I26) | J24: =SUM(J25:J26) | K24: =SUM(K25:K26) | ... O24: =SUM(O25:O26) | P24: =SUM(D24:O24) | Q24: =IFERROR(P24/$P$19, 0)
B25: 6.1 | C25: Despesas com Vendas | D25: =SUMIFS(DESPESAS!$H:$H, DESPESAS!$E:$E, "6.1 Despesas com Vendas", DESPESAS!$L:$L, 1, DESPESAS!$M:$M, $E$5, DESPESAS!$J:$J, "<>Cancelada") | E25: =SUMIFS(DESPESAS!$H:$H, DESPESAS!$E:$E, "6.1 Despesas com Vendas", DESPESAS!$L:$L, 2, DESPESAS!$M:$M, $E$5, DESPESAS!$J:$J, "<>Cancelada") | F25: =SUMIFS(DESPESAS!$H:$H, DESPESAS!$E:$E, "6.1 Despesas com Vendas", DESPESAS!$L:$L, 3, DESPESAS!$M:$M, $E$5, DESPESAS!$J:$J, "<>Cancelada") | G25: =SUMIFS(DESPESAS!$H:$H, DESPESAS!$E:$E, "6.1 Despesas com Vendas", DESPESAS!$L:$L, 4, DESPESAS!$M:$M, $E$5, DESPESAS!$J:$J, "<>Cancelada") | H25: =SUMIFS(DESPESAS!$H:$H, DESPESAS!$E:$E, "6.1 Despesas com Vendas", DESPESAS!$L:$L, 5, DESPESAS!$M:$M, $E$5, DESPESAS!$J:$J, "<>Cancelada") | I25: =SUMIFS(DESPESAS!$H:$H, DESPESAS!$E:$E, "6.1 Despesas com Vendas", DESPESAS!$L:$L, 6, DESPESAS!$M:$M, $E$5, DESPESAS!$J:$J, "<>Cancelada") | J25: =SUMIFS(DESPESAS!$H:$H, DESPESAS!$E:$E, "6.1 Despesas com Vendas", DESPESAS!$L:$L, 7, DESPESAS!$M:$M, $E$5, DESPESAS!$J:$J, "<>Cancelada") | K25: =SUMIFS(DESPESAS!$H:$H, DESPESAS!$E:$E, "6.1 Despesas com Vendas", DESPESAS!$L:$L, 8, DESPESAS!$M:$M, $E$5, DESPESAS!$J:$J, "<>Cancelada") | L25: =SUMIFS(DESPESAS!$H:$H, DESPESAS!$E:$E, "6.1 Despesas com Vendas", DESPESAS!$L:$L, 9, DESPESAS!$M:$M, $E$5, DESPESAS!$J:$J, "<>Cancelada") | M25: =SUMIFS(DESPESAS!$H:$H, DESPESAS!$E:$E, "6.1 Despesas com Vendas", DESPESAS!$L:$L, 10, DESPESAS!$M:$M, $E$5, DESPESAS!$J:$J, "<>Cancelada") | N25: =SUMIFS(DESPESAS!$H:$H, DESPESAS!$E:$E, "6.1 Despesas com Vendas", DESPESAS!$L:$L, 11, DESPESAS!$M:$M, $E$5, DESPESAS!$J:$J, "<>Cancelada") | O25: =SUMIFS(DESPESAS!$H:$H, DESPESAS!$E:$E, "6.1 Despesas com Vendas", DESPESAS!$L:$L, 12, DESPESAS!$M:$M, $E$5, DESPESAS!$J:$J, "<>Cancelada") | P25: =SUM(D25:O25) | Q25: =IFERROR(P25/$P$19, 0)
B26: 6.2 | C26: Despesas Administrativas (água, luz, telefone, aluguel, folha, etc.) | D26: =SUMIFS(DESPESAS!$H:$H, DESPESAS!$E:$E, "6.2 Despesas Administrativas", DESPESAS!$L:$L, 1, DESPESAS!$M:$M, $E$5, DESPESAS!$J:$J, "<>Cancelada") | E26: =SUMIFS(DESPESAS!$H:$H, DESPESAS!$E:$E, "6.2 Despesas Administrativas", DESPESAS!$L:$L, 2, DESPESAS!$M:$M, $E$5, DESPESAS!$J:$J, "<>Cancelada") | F26: =SUMIFS(DESPESAS!$H:$H, DESPESAS!$E:$E, "6.2 Despesas Administrativas", DESPESAS!$L:$L, 3, DESPESAS!$M:$M, $E$5, DESPESAS!$J:$J, "<>Cancelada") | G26: =SUMIFS(DESPESAS!$H:$H, DESPESAS!$E:$E, "6.2 Despesas Administrativas", DESPESAS!$L:$L, 4, DESPESAS!$M:$M, $E$5, DESPESAS!$J:$J, "<>Cancelada") | H26: =SUMIFS(DESPESAS!$H:$H, DESPESAS!$E:$E, "6.2 Despesas Administrativas", DESPESAS!$L:$L, 5, DESPESAS!$M:$M, $E$5, DESPESAS!$J:$J, "<>Cancelada") | I26: =SUMIFS(DESPESAS!$H:$H, DESPESAS!$E:$E, "6.2 Despesas Administrativas", DESPESAS!$L:$L, 6, DESPESAS!$M:$M, $E$5, DESPESAS!$J:$J, "<>Cancelada") | J26: =SUMIFS(DESPESAS!$H:$H, DESPESAS!$E:$E, "6.2 Despesas Administrativas", DESPESAS!$L:$L, 7, DESPESAS!$M:$M, $E$5, DESPESAS!$J:$J, "<>Cancelada") | K26: =SUMIFS(DESPESAS!$H:$H, DESPESAS!$E:$E, "6.2 Despesas Administrativas", DESPESAS!$L:$L, 8, DESPESAS!$M:$M, $E$5, DESPESAS!$J:$J, "<>Cancelada") | L26: =SUMIFS(DESPESAS!$H:$H, DESPESAS!$E:$E, "6.2 Despesas Administrativas", DESPESAS!$L:$L, 9, DESPESAS!$M:$M, $E$5, DESPESAS!$J:$J, "<>Cancelada") | M26: =SUMIFS(DESPESAS!$H:$H, DESPESAS!$E:$E, "6.2 Despesas Administrativas", DESPESAS!$L:$L, 10, DESPESAS!$M:$M, $E$5, DESPESAS!$J:$J, "<>Cancelada") | N26: =SUMIFS(DESPESAS!$H:$H, DESPESAS!$E:$E, "6.2 Despesas Administrativas", DESPESAS!$L:$L, 11, DESPESAS!$M:$M, $E$5, DESPESAS!$J:$J, "<>Cancelada") | O26: =SUMIFS(DESPESAS!$H:$H, DESPESAS!$E:$E, "6.2 Despesas Administrativas", DESPESAS!$L:$L, 12, DESPESAS!$M:$M, $E$5, DESPESAS!$J:$J, "<>Cancelada") | P26: =SUM(D26:O26) | Q26: =IFERROR(P26/$P$19, 0)
B27: 7 | C27: Receitas Financeiras Líquidas | D27: =SUM(D28:D29) | E27: =SUM(E28:E29) | F27: =SUM(F28:F29) | G27: =SUM(G28:G29) | H27: =SUM(H28:H29) | I27: =SUM(I28:I29) | J27: =SUM(J28:J29) | K27: =SUM(K28:K29) | ... O27: =SUM(O28:O29) | P27: =SUM(D27:O27) | Q27: =IFERROR(P27/$P$19, 0)
B28: 7.1 | C28: Receitas Financeiras | D28: =SUMIFS(DESPESAS!$H:$H, DESPESAS!$E:$E, "7.1 Receitas Financeiras", DESPESAS!$L:$L, 1, DESPESAS!$M:$M, $E$5, DESPESAS!$J:$J, "<>Cancelada") | E28: =SUMIFS(DESPESAS!$H:$H, DESPESAS!$E:$E, "7.1 Receitas Financeiras", DESPESAS!$L:$L, 2, DESPESAS!$M:$M, $E$5, DESPESAS!$J:$J, "<>Cancelada") | F28: =SUMIFS(DESPESAS!$H:$H, DESPESAS!$E:$E, "7.1 Receitas Financeiras", DESPESAS!$L:$L, 3, DESPESAS!$M:$M, $E$5, DESPESAS!$J:$J, "<>Cancelada") | G28: =SUMIFS(DESPESAS!$H:$H, DESPESAS!$E:$E, "7.1 Receitas Financeiras", DESPESAS!$L:$L, 4, DESPESAS!$M:$M, $E$5, DESPESAS!$J:$J, "<>Cancelada") | H28: =SUMIFS(DESPESAS!$H:$H, DESPESAS!$E:$E, "7.1 Receitas Financeiras", DESPESAS!$L:$L, 5, DESPESAS!$M:$M, $E$5, DESPESAS!$J:$J, "<>Cancelada") | I28: =SUMIFS(DESPESAS!$H:$H, DESPESAS!$E:$E, "7.1 Receitas Financeiras", DESPESAS!$L:$L, 6, DESPESAS!$M:$M, $E$5, DESPESAS!$J:$J, "<>Cancelada") | J28: =SUMIFS(DESPESAS!$H:$H, DESPESAS!$E:$E, "7.1 Receitas Financeiras", DESPESAS!$L:$L, 7, DESPESAS!$M:$M, $E$5, DESPESAS!$J:$J, "<>Cancelada") | K28: =SUMIFS(DESPESAS!$H:$H, DESPESAS!$E:$E, "7.1 Receitas Financeiras", DESPESAS!$L:$L, 8, DESPESAS!$M:$M, $E$5, DESPESAS!$J:$J, "<>Cancelada") | L28: =SUMIFS(DESPESAS!$H:$H, DESPESAS!$E:$E, "7.1 Receitas Financeiras", DESPESAS!$L:$L, 9, DESPESAS!$M:$M, $E$5, DESPESAS!$J:$J, "<>Cancelada") | M28: =SUMIFS(DESPESAS!$H:$H, DESPESAS!$E:$E, "7.1 Receitas Financeiras", DESPESAS!$L:$L, 10, DESPESAS!$M:$M, $E$5, DESPESAS!$J:$J, "<>Cancelada") | N28: =SUMIFS(DESPESAS!$H:$H, DESPESAS!$E:$E, "7.1 Receitas Financeiras", DESPESAS!$L:$L, 11, DESPESAS!$M:$M, $E$5, DESPESAS!$J:$J, "<>Cancelada") | O28: =SUMIFS(DESPESAS!$H:$H, DESPESAS!$E:$E, "7.1 Receitas Financeiras", DESPESAS!$L:$L, 12, DESPESAS!$M:$M, $E$5, DESPESAS!$J:$J, "<>Cancelada") | P28: =SUM(D28:O28) | Q28: =IFERROR(P28/$P$19, 0)
B29: 7.2 | C29: Variações Monetárias e Cambiais Ativas | D29: =SUMIFS(DESPESAS!$H:$H, DESPESAS!$E:$E, "7.2 Variações Monetárias e Cambiais Ativas", DESPESAS!$L:$L, 1, DESPESAS!$M:$M, $E$5, DESPESAS!$J:$J, "<>Cancelada") | E29: =SUMIFS(DESPESAS!$H:$H, DESPESAS!$E:$E, "7.2 Variações Monetárias e Cambiais Ativas", DESPESAS!$L:$L, 2, DESPESAS!$M:$M, $E$5, DESPESAS!$J:$J, "<>Cancelada") | F29: =SUMIFS(DESPESAS!$H:$H, DESPESAS!$E:$E, "7.2 Variações Monetárias e Cambiais Ativas", DESPESAS!$L:$L, 3, DESPESAS!$M:$M, $E$5, DESPESAS!$J:$J, "<>Cancelada") | G29: =SUMIFS(DESPESAS!$H:$H, DESPESAS!$E:$E, "7.2 Variações Monetárias e Cambiais Ativas", DESPESAS!$L:$L, 4, DESPESAS!$M:$M, $E$5, DESPESAS!$J:$J, "<>Cancelada") | H29: =SUMIFS(DESPESAS!$H:$H, DESPESAS!$E:$E, "7.2 Variações Monetárias e Cambiais Ativas", DESPESAS!$L:$L, 5, DESPESAS!$M:$M, $E$5, DESPESAS!$J:$J, "<>Cancelada") | I29: =SUMIFS(DESPESAS!$H:$H, DESPESAS!$E:$E, "7.2 Variações Monetárias e Cambiais Ativas", DESPESAS!$L:$L, 6, DESPESAS!$M:$M, $E$5, DESPESAS!$J:$J, "<>Cancelada") | J29: =SUMIFS(DESPESAS!$H:$H, DESPESAS!$E:$E, "7.2 Variações Monetárias e Cambiais Ativas", DESPESAS!$L:$L, 7, DESPESAS!$M:$M, $E$5, DESPESAS!$J:$J, "<>Cancelada") | K29: =SUMIFS(DESPESAS!$H:$H, DESPESAS!$E:$E, "7.2 Variações Monetárias e Cambiais Ativas", DESPESAS!$L:$L, 8, DESPESAS!$M:$M, $E$5, DESPESAS!$J:$J, "<>Cancelada") | L29: =SUMIFS(DESPESAS!$H:$H, DESPESAS!$E:$E, "7.2 Variações Monetárias e Cambiais Ativas", DESPESAS!$L:$L, 9, DESPESAS!$M:$M, $E$5, DESPESAS!$J:$J, "<>Cancelada") | M29: =SUMIFS(DESPESAS!$H:$H, DESPESAS!$E:$E, "7.2 Variações Monetárias e Cambiais Ativas", DESPESAS!$L:$L, 10, DESPESAS!$M:$M, $E$5, DESPESAS!$J:$J, "<>Cancelada") | N29: =SUMIFS(DESPESAS!$H:$H, DESPESAS!$E:$E, "7.2 Variações Monetárias e Cambiais Ativas", DESPESAS!$L:$L, 11, DESPESAS!$M:$M, $E$5, DESPESAS!$J:$J, "<>Cancelada") | O29: =SUMIFS(DESPESAS!$H:$H, DESPESAS!$E:$E, "7.2 Variações Monetárias e Cambiais Ativas", DESPESAS!$L:$L, 12, DESPESAS!$M:$M, $E$5, DESPESAS!$J:$J, "<>Cancelada") | P29: =SUM(D29:O29) | Q29: =IFERROR(P29/$P$19, 0)
B30: 8 | C30: Despesas Financeiras Líquidas | D30: =SUM(D31:D32) | E30: =SUM(E31:E32) | F30: =SUM(F31:F32) | G30: =SUM(G31:G32) | H30: =SUM(H31:H32) | I30: =SUM(I31:I32) | J30: =SUM(J31:J32) | K30: =SUM(K31:K32) | ... O30: =SUM(O31:O32) | P30: =SUM(D30:O30) | Q30: =IFERROR(P30/$P$19, 0)
B31: 8.1 | C31: Despesas Financeiras (Taxas Cartão PDV, Juros e Tarifas Bancos) | D31: =0+SUMIFS(DESPESAS!$H:$H,DESPESAS!$E:$E,"8.1 Despesas Financeiras",DESPESAS!$L:$L,1,DESPESAS!$M:$M,$E$5,DESPESAS!$J:$J,"<>Cancelada") | E31: =0+SUMIFS(DESPESAS!$H:$H,DESPESAS!$E:$E,"8.1 Despesas Financeiras",DESPESAS!$L:$L,2,DESPESAS!$M:$M,$E$5,DESPESAS!$J:$J,"<>Cancelada") | F31: =0+SUMIFS(DESPESAS!$H:$H,DESPESAS!$E:$E,"8.1 Despesas Financeiras",DESPESAS!$L:$L,3,DESPESAS!$M:$M,$E$5,DESPESAS!$J:$J,"<>Cancelada") | G31: =0+SUMIFS(DESPESAS!$H:$H,DESPESAS!$E:$E,"8.1 Despesas Financeiras",DESPESAS!$L:$L,4,DESPESAS!$M:$M,$E$5,DESPESAS!$J:$J,"<>Cancelada") | H31: =0+SUMIFS(DESPESAS!$H:$H,DESPESAS!$E:$E,"8.1 Despesas Financeiras",DESPESAS!$L:$L,5,DESPESAS!$M:$M,$E$5,DESPESAS!$J:$J,"<>Cancelada") | I31: =0+SUMIFS(DESPESAS!$H:$H,DESPESAS!$E:$E,"8.1 Despesas Financeiras",DESPESAS!$L:$L,6,DESPESAS!$M:$M,$E$5,DESPESAS!$J:$J,"<>Cancelada") | J31: =0+SUMIFS(DESPESAS!$H:$H,DESPESAS!$E:$E,"8.1 Despesas Financeiras",DESPESAS!$L:$L,7,DESPESAS!$M:$M,$E$5,DESPESAS!$J:$J,"<>Cancelada") | K31: =0+SUMIFS(DESPESAS!$H:$H,DESPESAS!$E:$E,"8.1 Despesas Financeiras",DESPESAS!$L:$L,8,DESPESAS!$M:$M,$E$5,DESPESAS!$J:$J,"<>Cancelada") | L31: =0+SUMIFS(DESPESAS!$H:$H,DESPESAS!$E:$E,"8.1 Despesas Financeiras",DESPESAS!$L:$L,9,DESPESAS!$M:$M,$E$5,DESPESAS!$J:$J,"<>Cancelada") | M31: =146.19+SUMIFS(DESPESAS!$H:$H,DESPESAS!$E:$E,"8.1 Despesas Financeiras",DESPESAS!$L:$L,10,DESPESAS!$M:$M,$E$5,DESPESAS!$J:$J,"<>Cancelada") | N31: =0+SUMIFS(DESPESAS!$H:$H,DESPESAS!$E:$E,"8.1 Despesas Financeiras",DESPESAS!$L:$L,11,DESPESAS!$M:$M,$E$5,DESPESAS!$J:$J,"<>Cancelada") | O31: =0+SUMIFS(DESPESAS!$H:$H,DESPESAS!$E:$E,"8.1 Despesas Financeiras",DESPESAS!$L:$L,12,DESPESAS!$M:$M,$E$5,DESPESAS!$J:$J,"<>Cancelada") | P31: =SUM(D31:O31) | Q31: =IFERROR(P31/$P$19, 0)
B32: 8.2 | C32: Variações Monetárias e Cambiais Passivas | D32: =SUMIFS(DESPESAS!$H:$H, DESPESAS!$E:$E, "8.2 Variações Monetárias e Cambiais Passivas", DESPESAS!$L:$L, 1, DESPESAS!$M:$M, $E$5, DESPESAS!$J:$J, "<>Cancelada") | E32: =SUMIFS(DESPESAS!$H:$H, DESPESAS!$E:$E, "8.2 Variações Monetárias e Cambiais Passivas", DESPESAS!$L:$L, 2, DESPESAS!$M:$M, $E$5, DESPESAS!$J:$J, "<>Cancelada") | F32: =SUMIFS(DESPESAS!$H:$H, DESPESAS!$E:$E, "8.2 Variações Monetárias e Cambiais Passivas", DESPESAS!$L:$L, 3, DESPESAS!$M:$M, $E$5, DESPESAS!$J:$J, "<>Cancelada") | G32: =SUMIFS(DESPESAS!$H:$H, DESPESAS!$E:$E, "8.2 Variações Monetárias e Cambiais Passivas", DESPESAS!$L:$L, 4, DESPESAS!$M:$M, $E$5, DESPESAS!$J:$J, "<>Cancelada") | H32: =SUMIFS(DESPESAS!$H:$H, DESPESAS!$E:$E, "8.2 Variações Monetárias e Cambiais Passivas", DESPESAS!$L:$L, 5, DESPESAS!$M:$M, $E$5, DESPESAS!$J:$J, "<>Cancelada") | I32: =SUMIFS(DESPESAS!$H:$H, DESPESAS!$E:$E, "8.2 Variações Monetárias e Cambiais Passivas", DESPESAS!$L:$L, 6, DESPESAS!$M:$M, $E$5, DESPESAS!$J:$J, "<>Cancelada") | J32: =SUMIFS(DESPESAS!$H:$H, DESPESAS!$E:$E, "8.2 Variações Monetárias e Cambiais Passivas", DESPESAS!$L:$L, 7, DESPESAS!$M:$M, $E$5, DESPESAS!$J:$J, "<>Cancelada") | K32: =SUMIFS(DESPESAS!$H:$H, DESPESAS!$E:$E, "8.2 Variações Monetárias e Cambiais Passivas", DESPESAS!$L:$L, 8, DESPESAS!$M:$M, $E$5, DESPESAS!$J:$J, "<>Cancelada") | L32: =SUMIFS(DESPESAS!$H:$H, DESPESAS!$E:$E, "8.2 Variações Monetárias e Cambiais Passivas", DESPESAS!$L:$L, 9, DESPESAS!$M:$M, $E$5, DESPESAS!$J:$J, "<>Cancelada") | M32: =SUMIFS(DESPESAS!$H:$H, DESPESAS!$E:$E, "8.2 Variações Monetárias e Cambiais Passivas", DESPESAS!$L:$L, 10, DESPESAS!$M:$M, $E$5, DESPESAS!$J:$J, "<>Cancelada") | N32: =SUMIFS(DESPESAS!$H:$H, DESPESAS!$E:$E, "8.2 Variações Monetárias e Cambiais Passivas", DESPESAS!$L:$L, 11, DESPESAS!$M:$M, $E$5, DESPESAS!$J:$J, "<>Cancelada") | O32: =SUMIFS(DESPESAS!$H:$H, DESPESAS!$E:$E, "8.2 Variações Monetárias e Cambiais Passivas", DESPESAS!$L:$L, 12, DESPESAS!$M:$M, $E$5, DESPESAS!$J:$J, "<>Cancelada") | P32: =SUM(D32:O32) | Q32: =IFERROR(P32/$P$19, 0)
B33: 9 | C33: Resultado Financeiro Líquido (7 - 8) | D33: =D27-D30 | E33: =E27-E30 | F33: =F27-F30 | G33: =G27-G30 | H33: =H27-H30 | I33: =I27-I30 | J33: =J27-J30 | K33: =K27-K30 | ... O33: =O27-O30 | P33: =SUM(D33:O33) | Q33: =IFERROR(P33/$P$19, 0)
B34: 10 | C34: Outras Receitas | D34: =SUM(D35:D36) | E34: =SUM(E35:E36) | F34: =SUM(F35:F36) | G34: =SUM(G35:G36) | H34: =SUM(H35:H36) | I34: =SUM(I35:I36) | J34: =SUM(J35:J36) | K34: =SUM(K35:K36) | ... O34: =SUM(O35:O36) | P34: =SUM(D34:O34) | Q34: =IFERROR(P34/$P$19, 0)
B35: 10.1 | C35: Resultado de Equivalência Patrimonial | D35: =SUMIFS(DESPESAS!$H:$H, DESPESAS!$E:$E, "10.1 Resultado de Equivalência Patrimonial", DESPESAS!$L:$L, 1, DESPESAS!$M:$M, $E$5, DESPESAS!$J:$J, "<>Cancelada") | E35: =SUMIFS(DESPESAS!$H:$H, DESPESAS!$E:$E, "10.1 Resultado de Equivalência Patrimonial", DESPESAS!$L:$L, 2, DESPESAS!$M:$M, $E$5, DESPESAS!$J:$J, "<>Cancelada") | F35: =SUMIFS(DESPESAS!$H:$H, DESPESAS!$E:$E, "10.1 Resultado de Equivalência Patrimonial", DESPESAS!$L:$L, 3, DESPESAS!$M:$M, $E$5, DESPESAS!$J:$J, "<>Cancelada") | G35: =SUMIFS(DESPESAS!$H:$H, DESPESAS!$E:$E, "10.1 Resultado de Equivalência Patrimonial", DESPESAS!$L:$L, 4, DESPESAS!$M:$M, $E$5, DESPESAS!$J:$J, "<>Cancelada") | H35: =SUMIFS(DESPESAS!$H:$H, DESPESAS!$E:$E, "10.1 Resultado de Equivalência Patrimonial", DESPESAS!$L:$L, 5, DESPESAS!$M:$M, $E$5, DESPESAS!$J:$J, "<>Cancelada") | I35: =SUMIFS(DESPESAS!$H:$H, DESPESAS!$E:$E, "10.1 Resultado de Equivalência Patrimonial", DESPESAS!$L:$L, 6, DESPESAS!$M:$M, $E$5, DESPESAS!$J:$J, "<>Cancelada") | J35: =SUMIFS(DESPESAS!$H:$H, DESPESAS!$E:$E, "10.1 Resultado de Equivalência Patrimonial", DESPESAS!$L:$L, 7, DESPESAS!$M:$M, $E$5, DESPESAS!$J:$J, "<>Cancelada") | K35: =SUMIFS(DESPESAS!$H:$H, DESPESAS!$E:$E, "10.1 Resultado de Equivalência Patrimonial", DESPESAS!$L:$L, 8, DESPESAS!$M:$M, $E$5, DESPESAS!$J:$J, "<>Cancelada") | L35: =SUMIFS(DESPESAS!$H:$H, DESPESAS!$E:$E, "10.1 Resultado de Equivalência Patrimonial", DESPESAS!$L:$L, 9, DESPESAS!$M:$M, $E$5, DESPESAS!$J:$J, "<>Cancelada") | M35: =SUMIFS(DESPESAS!$H:$H, DESPESAS!$E:$E, "10.1 Resultado de Equivalência Patrimonial", DESPESAS!$L:$L, 10, DESPESAS!$M:$M, $E$5, DESPESAS!$J:$J, "<>Cancelada") | N35: =SUMIFS(DESPESAS!$H:$H, DESPESAS!$E:$E, "10.1 Resultado de Equivalência Patrimonial", DESPESAS!$L:$L, 11, DESPESAS!$M:$M, $E$5, DESPESAS!$J:$J, "<>Cancelada") | O35: =SUMIFS(DESPESAS!$H:$H, DESPESAS!$E:$E, "10.1 Resultado de Equivalência Patrimonial", DESPESAS!$L:$L, 12, DESPESAS!$M:$M, $E$5, DESPESAS!$J:$J, "<>Cancelada") | P35: =SUM(D35:O35) | Q35: =IFERROR(P35/$P$19, 0)
B36: 10.2 | C36: Venda de Bens e Direitos do Ativo Não Circulante | D36: =SUMIFS(DESPESAS!$H:$H, DESPESAS!$E:$E, "10.2 Venda de Bens e Direitos do Ativo Não Circulante", DESPESAS!$L:$L, 1, DESPESAS!$M:$M, $E$5, DESPESAS!$J:$J, "<>Cancelada") | E36: =SUMIFS(DESPESAS!$H:$H, DESPESAS!$E:$E, "10.2 Venda de Bens e Direitos do Ativo Não Circulante", DESPESAS!$L:$L, 2, DESPESAS!$M:$M, $E$5, DESPESAS!$J:$J, "<>Cancelada") | F36: =SUMIFS(DESPESAS!$H:$H, DESPESAS!$E:$E, "10.2 Venda de Bens e Direitos do Ativo Não Circulante", DESPESAS!$L:$L, 3, DESPESAS!$M:$M, $E$5, DESPESAS!$J:$J, "<>Cancelada") | G36: =SUMIFS(DESPESAS!$H:$H, DESPESAS!$E:$E, "10.2 Venda de Bens e Direitos do Ativo Não Circulante", DESPESAS!$L:$L, 4, DESPESAS!$M:$M, $E$5, DESPESAS!$J:$J, "<>Cancelada") | H36: =SUMIFS(DESPESAS!$H:$H, DESPESAS!$E:$E, "10.2 Venda de Bens e Direitos do Ativo Não Circulante", DESPESAS!$L:$L, 5, DESPESAS!$M:$M, $E$5, DESPESAS!$J:$J, "<>Cancelada") | I36: =SUMIFS(DESPESAS!$H:$H, DESPESAS!$E:$E, "10.2 Venda de Bens e Direitos do Ativo Não Circulante", DESPESAS!$L:$L, 6, DESPESAS!$M:$M, $E$5, DESPESAS!$J:$J, "<>Cancelada") | J36: =SUMIFS(DESPESAS!$H:$H, DESPESAS!$E:$E, "10.2 Venda de Bens e Direitos do Ativo Não Circulante", DESPESAS!$L:$L, 7, DESPESAS!$M:$M, $E$5, DESPESAS!$J:$J, "<>Cancelada") | K36: =SUMIFS(DESPESAS!$H:$H, DESPESAS!$E:$E, "10.2 Venda de Bens e Direitos do Ativo Não Circulante", DESPESAS!$L:$L, 8, DESPESAS!$M:$M, $E$5, DESPESAS!$J:$J, "<>Cancelada") | L36: =SUMIFS(DESPESAS!$H:$H, DESPESAS!$E:$E, "10.2 Venda de Bens e Direitos do Ativo Não Circulante", DESPESAS!$L:$L, 9, DESPESAS!$M:$M, $E$5, DESPESAS!$J:$J, "<>Cancelada") | M36: =SUMIFS(DESPESAS!$H:$H, DESPESAS!$E:$E, "10.2 Venda de Bens e Direitos do Ativo Não Circulante", DESPESAS!$L:$L, 10, DESPESAS!$M:$M, $E$5, DESPESAS!$J:$J, "<>Cancelada") | N36: =SUMIFS(DESPESAS!$H:$H, DESPESAS!$E:$E, "10.2 Venda de Bens e Direitos do Ativo Não Circulante", DESPESAS!$L:$L, 11, DESPESAS!$M:$M, $E$5, DESPESAS!$J:$J, "<>Cancelada") | O36: =SUMIFS(DESPESAS!$H:$H, DESPESAS!$E:$E, "10.2 Venda de Bens e Direitos do Ativo Não Circulante", DESPESAS!$L:$L, 12, DESPESAS!$M:$M, $E$5, DESPESAS!$J:$J, "<>Cancelada") | P36: =SUM(D36:O36) | Q36: =IFERROR(P36/$P$19, 0)
B37: 11 | C37: Outras Despesas | D37: =SUM(D38:D44) | E37: =SUM(E38:E44) | F37: =SUM(F38:F44) | G37: =SUM(G38:G44) | H37: =SUM(H38:H44) | I37: =SUM(I38:I44) | J37: =SUM(J38:J44) | K37: =SUM(K38:K44) | ... O37: =SUM(O38:O44) | P37: =SUM(D37:O37) | Q37: =IFERROR(P37/$P$19, 0)
B38: 11.1 | C38: Serviços de contabilidade | D38: =SUMIFS(DESPESAS!$H:$H, DESPESAS!$E:$E, "11.1 Serviços de contabilidade", DESPESAS!$L:$L, 1, DESPESAS!$M:$M, $E$5, DESPESAS!$J:$J, "<>Cancelada") | E38: =SUMIFS(DESPESAS!$H:$H, DESPESAS!$E:$E, "11.1 Serviços de contabilidade", DESPESAS!$L:$L, 2, DESPESAS!$M:$M, $E$5, DESPESAS!$J:$J, "<>Cancelada") | F38: =SUMIFS(DESPESAS!$H:$H, DESPESAS!$E:$E, "11.1 Serviços de contabilidade", DESPESAS!$L:$L, 3, DESPESAS!$M:$M, $E$5, DESPESAS!$J:$J, "<>Cancelada") | G38: =SUMIFS(DESPESAS!$H:$H, DESPESAS!$E:$E, "11.1 Serviços de contabilidade", DESPESAS!$L:$L, 4, DESPESAS!$M:$M, $E$5, DESPESAS!$J:$J, "<>Cancelada") | H38: =SUMIFS(DESPESAS!$H:$H, DESPESAS!$E:$E, "11.1 Serviços de contabilidade", DESPESAS!$L:$L, 5, DESPESAS!$M:$M, $E$5, DESPESAS!$J:$J, "<>Cancelada") | I38: =SUMIFS(DESPESAS!$H:$H, DESPESAS!$E:$E, "11.1 Serviços de contabilidade", DESPESAS!$L:$L, 6, DESPESAS!$M:$M, $E$5, DESPESAS!$J:$J, "<>Cancelada") | J38: =SUMIFS(DESPESAS!$H:$H, DESPESAS!$E:$E, "11.1 Serviços de contabilidade", DESPESAS!$L:$L, 7, DESPESAS!$M:$M, $E$5, DESPESAS!$J:$J, "<>Cancelada") | K38: =SUMIFS(DESPESAS!$H:$H, DESPESAS!$E:$E, "11.1 Serviços de contabilidade", DESPESAS!$L:$L, 8, DESPESAS!$M:$M, $E$5, DESPESAS!$J:$J, "<>Cancelada") | L38: =SUMIFS(DESPESAS!$H:$H, DESPESAS!$E:$E, "11.1 Serviços de contabilidade", DESPESAS!$L:$L, 9, DESPESAS!$M:$M, $E$5, DESPESAS!$J:$J, "<>Cancelada") | M38: =SUMIFS(DESPESAS!$H:$H, DESPESAS!$E:$E, "11.1 Serviços de contabilidade", DESPESAS!$L:$L, 10, DESPESAS!$M:$M, $E$5, DESPESAS!$J:$J, "<>Cancelada") | N38: =SUMIFS(DESPESAS!$H:$H, DESPESAS!$E:$E, "11.1 Serviços de contabilidade", DESPESAS!$L:$L, 11, DESPESAS!$M:$M, $E$5, DESPESAS!$J:$J, "<>Cancelada") | O38: =SUMIFS(DESPESAS!$H:$H, DESPESAS!$E:$E, "11.1 Serviços de contabilidade", DESPESAS!$L:$L, 12, DESPESAS!$M:$M, $E$5, DESPESAS!$J:$J, "<>Cancelada") | P38: =SUM(D38:O38) | Q38: =IFERROR(P38/$P$19, 0)
B39: 11.2 | C39: Manutenção de veículos | D39: =SUMIFS(DESPESAS!$H:$H, DESPESAS!$E:$E, "11.2 Manutenção de veículos", DESPESAS!$L:$L, 1, DESPESAS!$M:$M, $E$5, DESPESAS!$J:$J, "<>Cancelada") | E39: =SUMIFS(DESPESAS!$H:$H, DESPESAS!$E:$E, "11.2 Manutenção de veículos", DESPESAS!$L:$L, 2, DESPESAS!$M:$M, $E$5, DESPESAS!$J:$J, "<>Cancelada") | F39: =SUMIFS(DESPESAS!$H:$H, DESPESAS!$E:$E, "11.2 Manutenção de veículos", DESPESAS!$L:$L, 3, DESPESAS!$M:$M, $E$5, DESPESAS!$J:$J, "<>Cancelada") | G39: =SUMIFS(DESPESAS!$H:$H, DESPESAS!$E:$E, "11.2 Manutenção de veículos", DESPESAS!$L:$L, 4, DESPESAS!$M:$M, $E$5, DESPESAS!$J:$J, "<>Cancelada") | H39: =SUMIFS(DESPESAS!$H:$H, DESPESAS!$E:$E, "11.2 Manutenção de veículos", DESPESAS!$L:$L, 5, DESPESAS!$M:$M, $E$5, DESPESAS!$J:$J, "<>Cancelada") | I39: =SUMIFS(DESPESAS!$H:$H, DESPESAS!$E:$E, "11.2 Manutenção de veículos", DESPESAS!$L:$L, 6, DESPESAS!$M:$M, $E$5, DESPESAS!$J:$J, "<>Cancelada") | J39: =SUMIFS(DESPESAS!$H:$H, DESPESAS!$E:$E, "11.2 Manutenção de veículos", DESPESAS!$L:$L, 7, DESPESAS!$M:$M, $E$5, DESPESAS!$J:$J, "<>Cancelada") | K39: =SUMIFS(DESPESAS!$H:$H, DESPESAS!$E:$E, "11.2 Manutenção de veículos", DESPESAS!$L:$L, 8, DESPESAS!$M:$M, $E$5, DESPESAS!$J:$J, "<>Cancelada") | L39: =SUMIFS(DESPESAS!$H:$H, DESPESAS!$E:$E, "11.2 Manutenção de veículos", DESPESAS!$L:$L, 9, DESPESAS!$M:$M, $E$5, DESPESAS!$J:$J, "<>Cancelada") | M39: =SUMIFS(DESPESAS!$H:$H, DESPESAS!$E:$E, "11.2 Manutenção de veículos", DESPESAS!$L:$L, 10, DESPESAS!$M:$M, $E$5, DESPESAS!$J:$J, "<>Cancelada") | N39: =SUMIFS(DESPESAS!$H:$H, DESPESAS!$E:$E, "11.2 Manutenção de veículos", DESPESAS!$L:$L, 11, DESPESAS!$M:$M, $E$5, DESPESAS!$J:$J, "<>Cancelada") | O39: =SUMIFS(DESPESAS!$H:$H, DESPESAS!$E:$E, "11.2 Manutenção de veículos", DESPESAS!$L:$L, 12, DESPESAS!$M:$M, $E$5, DESPESAS!$J:$J, "<>Cancelada") | P39: =SUM(D39:O39) | Q39: =IFERROR(P39/$P$19, 0)
B40: 11.3 | C40: Manutenção da empresa | D40: =SUMIFS(DESPESAS!$H:$H, DESPESAS!$E:$E, "11.3 Manutenção da empresa", DESPESAS!$L:$L, 1, DESPESAS!$M:$M, $E$5, DESPESAS!$J:$J, "<>Cancelada") | E40: =SUMIFS(DESPESAS!$H:$H, DESPESAS!$E:$E, "11.3 Manutenção da empresa", DESPESAS!$L:$L, 2, DESPESAS!$M:$M, $E$5, DESPESAS!$J:$J, "<>Cancelada") | F40: =SUMIFS(DESPESAS!$H:$H, DESPESAS!$E:$E, "11.3 Manutenção da empresa", DESPESAS!$L:$L, 3, DESPESAS!$M:$M, $E$5, DESPESAS!$J:$J, "<>Cancelada") | G40: =SUMIFS(DESPESAS!$H:$H, DESPESAS!$E:$E, "11.3 Manutenção da empresa", DESPESAS!$L:$L, 4, DESPESAS!$M:$M, $E$5, DESPESAS!$J:$J, "<>Cancelada") | H40: =SUMIFS(DESPESAS!$H:$H, DESPESAS!$E:$E, "11.3 Manutenção da empresa", DESPESAS!$L:$L, 5, DESPESAS!$M:$M, $E$5, DESPESAS!$J:$J, "<>Cancelada") | I40: =SUMIFS(DESPESAS!$H:$H, DESPESAS!$E:$E, "11.3 Manutenção da empresa", DESPESAS!$L:$L, 6, DESPESAS!$M:$M, $E$5, DESPESAS!$J:$J, "<>Cancelada") | J40: =SUMIFS(DESPESAS!$H:$H, DESPESAS!$E:$E, "11.3 Manutenção da empresa", DESPESAS!$L:$L, 7, DESPESAS!$M:$M, $E$5, DESPESAS!$J:$J, "<>Cancelada") | K40: =SUMIFS(DESPESAS!$H:$H, DESPESAS!$E:$E, "11.3 Manutenção da empresa", DESPESAS!$L:$L, 8, DESPESAS!$M:$M, $E$5, DESPESAS!$J:$J, "<>Cancelada") | L40: =SUMIFS(DESPESAS!$H:$H, DESPESAS!$E:$E, "11.3 Manutenção da empresa", DESPESAS!$L:$L, 9, DESPESAS!$M:$M, $E$5, DESPESAS!$J:$J, "<>Cancelada") | M40: =SUMIFS(DESPESAS!$H:$H, DESPESAS!$E:$E, "11.3 Manutenção da empresa", DESPESAS!$L:$L, 10, DESPESAS!$M:$M, $E$5, DESPESAS!$J:$J, "<>Cancelada") | N40: =SUMIFS(DESPESAS!$H:$H, DESPESAS!$E:$E, "11.3 Manutenção da empresa", DESPESAS!$L:$L, 11, DESPESAS!$M:$M, $E$5, DESPESAS!$J:$J, "<>Cancelada") | O40: =SUMIFS(DESPESAS!$H:$H, DESPESAS!$E:$E, "11.3 Manutenção da empresa", DESPESAS!$L:$L, 12, DESPESAS!$M:$M, $E$5, DESPESAS!$J:$J, "<>Cancelada") | P40: =SUM(D40:O40) | Q40: =IFERROR(P40/$P$19, 0)
B41: 11.4 | C41: Seguro predial e instalação | D41: =SUMIFS(DESPESAS!$H:$H, DESPESAS!$E:$E, "11.4 Seguro predial e instalação", DESPESAS!$L:$L, 1, DESPESAS!$M:$M, $E$5, DESPESAS!$J:$J, "<>Cancelada") | E41: =SUMIFS(DESPESAS!$H:$H, DESPESAS!$E:$E, "11.4 Seguro predial e instalação", DESPESAS!$L:$L, 2, DESPESAS!$M:$M, $E$5, DESPESAS!$J:$J, "<>Cancelada") | F41: =SUMIFS(DESPESAS!$H:$H, DESPESAS!$E:$E, "11.4 Seguro predial e instalação", DESPESAS!$L:$L, 3, DESPESAS!$M:$M, $E$5, DESPESAS!$J:$J, "<>Cancelada") | G41: =SUMIFS(DESPESAS!$H:$H, DESPESAS!$E:$E, "11.4 Seguro predial e instalação", DESPESAS!$L:$L, 4, DESPESAS!$M:$M, $E$5, DESPESAS!$J:$J, "<>Cancelada") | H41: =SUMIFS(DESPESAS!$H:$H, DESPESAS!$E:$E, "11.4 Seguro predial e instalação", DESPESAS!$L:$L, 5, DESPESAS!$M:$M, $E$5, DESPESAS!$J:$J, "<>Cancelada") | I41: =SUMIFS(DESPESAS!$H:$H, DESPESAS!$E:$E, "11.4 Seguro predial e instalação", DESPESAS!$L:$L, 6, DESPESAS!$M:$M, $E$5, DESPESAS!$J:$J, "<>Cancelada") | J41: =SUMIFS(DESPESAS!$H:$H, DESPESAS!$E:$E, "11.4 Seguro predial e instalação", DESPESAS!$L:$L, 7, DESPESAS!$M:$M, $E$5, DESPESAS!$J:$J, "<>Cancelada") | K41: =SUMIFS(DESPESAS!$H:$H, DESPESAS!$E:$E, "11.4 Seguro predial e instalação", DESPESAS!$L:$L, 8, DESPESAS!$M:$M, $E$5, DESPESAS!$J:$J, "<>Cancelada") | L41: =SUMIFS(DESPESAS!$H:$H, DESPESAS!$E:$E, "11.4 Seguro predial e instalação", DESPESAS!$L:$L, 9, DESPESAS!$M:$M, $E$5, DESPESAS!$J:$J, "<>Cancelada") | M41: =SUMIFS(DESPESAS!$H:$H, DESPESAS!$E:$E, "11.4 Seguro predial e instalação", DESPESAS!$L:$L, 10, DESPESAS!$M:$M, $E$5, DESPESAS!$J:$J, "<>Cancelada") | N41: =SUMIFS(DESPESAS!$H:$H, DESPESAS!$E:$E, "11.4 Seguro predial e instalação", DESPESAS!$L:$L, 11, DESPESAS!$M:$M, $E$5, DESPESAS!$J:$J, "<>Cancelada") | O41: =SUMIFS(DESPESAS!$H:$H, DESPESAS!$E:$E, "11.4 Seguro predial e instalação", DESPESAS!$L:$L, 12, DESPESAS!$M:$M, $E$5, DESPESAS!$J:$J, "<>Cancelada") | P41: =SUM(D41:O41) | Q41: =IFERROR(P41/$P$19, 0)
B42: 11.5 | C42: Seguro produtos | D42: =SUMIFS(DESPESAS!$H:$H, DESPESAS!$E:$E, "11.5 Seguro produtos", DESPESAS!$L:$L, 1, DESPESAS!$M:$M, $E$5, DESPESAS!$J:$J, "<>Cancelada") | E42: =SUMIFS(DESPESAS!$H:$H, DESPESAS!$E:$E, "11.5 Seguro produtos", DESPESAS!$L:$L, 2, DESPESAS!$M:$M, $E$5, DESPESAS!$J:$J, "<>Cancelada") | F42: =SUMIFS(DESPESAS!$H:$H, DESPESAS!$E:$E, "11.5 Seguro produtos", DESPESAS!$L:$L, 3, DESPESAS!$M:$M, $E$5, DESPESAS!$J:$J, "<>Cancelada") | G42: =SUMIFS(DESPESAS!$H:$H, DESPESAS!$E:$E, "11.5 Seguro produtos", DESPESAS!$L:$L, 4, DESPESAS!$M:$M, $E$5, DESPESAS!$J:$J, "<>Cancelada") | H42: =SUMIFS(DESPESAS!$H:$H, DESPESAS!$E:$E, "11.5 Seguro produtos", DESPESAS!$L:$L, 5, DESPESAS!$M:$M, $E$5, DESPESAS!$J:$J, "<>Cancelada") | I42: =SUMIFS(DESPESAS!$H:$H, DESPESAS!$E:$E, "11.5 Seguro produtos", DESPESAS!$L:$L, 6, DESPESAS!$M:$M, $E$5, DESPESAS!$J:$J, "<>Cancelada") | J42: =SUMIFS(DESPESAS!$H:$H, DESPESAS!$E:$E, "11.5 Seguro produtos", DESPESAS!$L:$L, 7, DESPESAS!$M:$M, $E$5, DESPESAS!$J:$J, "<>Cancelada") | K42: =SUMIFS(DESPESAS!$H:$H, DESPESAS!$E:$E, "11.5 Seguro produtos", DESPESAS!$L:$L, 8, DESPESAS!$M:$M, $E$5, DESPESAS!$J:$J, "<>Cancelada") | L42: =SUMIFS(DESPESAS!$H:$H, DESPESAS!$E:$E, "11.5 Seguro produtos", DESPESAS!$L:$L, 9, DESPESAS!$M:$M, $E$5, DESPESAS!$J:$J, "<>Cancelada") | M42: =SUMIFS(DESPESAS!$H:$H, DESPESAS!$E:$E, "11.5 Seguro produtos", DESPESAS!$L:$L, 10, DESPESAS!$M:$M, $E$5, DESPESAS!$J:$J, "<>Cancelada") | N42: =SUMIFS(DESPESAS!$H:$H, DESPESAS!$E:$E, "11.5 Seguro produtos", DESPESAS!$L:$L, 11, DESPESAS!$M:$M, $E$5, DESPESAS!$J:$J, "<>Cancelada") | O42: =SUMIFS(DESPESAS!$H:$H, DESPESAS!$E:$E, "11.5 Seguro produtos", DESPESAS!$L:$L, 12, DESPESAS!$M:$M, $E$5, DESPESAS!$J:$J, "<>Cancelada") | P42: =SUM(D42:O42) | Q42: =IFERROR(P42/$P$19, 0)
B43: 11.6 | C43: Depreciação | D43: =SUMIFS(DESPESAS!$H:$H, DESPESAS!$E:$E, "11.6 Depreciação", DESPESAS!$L:$L, 1, DESPESAS!$M:$M, $E$5, DESPESAS!$J:$J, "<>Cancelada") | E43: =SUMIFS(DESPESAS!$H:$H, DESPESAS!$E:$E, "11.6 Depreciação", DESPESAS!$L:$L, 2, DESPESAS!$M:$M, $E$5, DESPESAS!$J:$J, "<>Cancelada") | F43: =SUMIFS(DESPESAS!$H:$H, DESPESAS!$E:$E, "11.6 Depreciação", DESPESAS!$L:$L, 3, DESPESAS!$M:$M, $E$5, DESPESAS!$J:$J, "<>Cancelada") | G43: =SUMIFS(DESPESAS!$H:$H, DESPESAS!$E:$E, "11.6 Depreciação", DESPESAS!$L:$L, 4, DESPESAS!$M:$M, $E$5, DESPESAS!$J:$J, "<>Cancelada") | H43: =SUMIFS(DESPESAS!$H:$H, DESPESAS!$E:$E, "11.6 Depreciação", DESPESAS!$L:$L, 5, DESPESAS!$M:$M, $E$5, DESPESAS!$J:$J, "<>Cancelada") | I43: =SUMIFS(DESPESAS!$H:$H, DESPESAS!$E:$E, "11.6 Depreciação", DESPESAS!$L:$L, 6, DESPESAS!$M:$M, $E$5, DESPESAS!$J:$J, "<>Cancelada") | J43: =SUMIFS(DESPESAS!$H:$H, DESPESAS!$E:$E, "11.6 Depreciação", DESPESAS!$L:$L, 7, DESPESAS!$M:$M, $E$5, DESPESAS!$J:$J, "<>Cancelada") | K43: =SUMIFS(DESPESAS!$H:$H, DESPESAS!$E:$E, "11.6 Depreciação", DESPESAS!$L:$L, 8, DESPESAS!$M:$M, $E$5, DESPESAS!$J:$J, "<>Cancelada") | L43: =SUMIFS(DESPESAS!$H:$H, DESPESAS!$E:$E, "11.6 Depreciação", DESPESAS!$L:$L, 9, DESPESAS!$M:$M, $E$5, DESPESAS!$J:$J, "<>Cancelada") | M43: =SUMIFS(DESPESAS!$H:$H, DESPESAS!$E:$E, "11.6 Depreciação", DESPESAS!$L:$L, 10, DESPESAS!$M:$M, $E$5, DESPESAS!$J:$J, "<>Cancelada") | N43: =SUMIFS(DESPESAS!$H:$H, DESPESAS!$E:$E, "11.6 Depreciação", DESPESAS!$L:$L, 11, DESPESAS!$M:$M, $E$5, DESPESAS!$J:$J, "<>Cancelada") | O43: =SUMIFS(DESPESAS!$H:$H, DESPESAS!$E:$E, "11.6 Depreciação", DESPESAS!$L:$L, 12, DESPESAS!$M:$M, $E$5, DESPESAS!$J:$J, "<>Cancelada") | P43: =SUM(D43:O43) | Q43: =IFERROR(P43/$P$19, 0)
B44: 11.7 | C44: Custo da Venda de Bens e Direitos do Ativo Não Circulante | D44: =SUMIFS(DESPESAS!$H:$H, DESPESAS!$E:$E, "11.7 Custo da Venda de Bens e Direitos do Ativo Não Circulante", DESPESAS!$L:$L, 1, DESPESAS!$M:$M, $E$5, DESPESAS!$J:$J, "<>Cancelada") | E44: =SUMIFS(DESPESAS!$H:$H, DESPESAS!$E:$E, "11.7 Custo da Venda de Bens e Direitos do Ativo Não Circulante", DESPESAS!$L:$L, 2, DESPESAS!$M:$M, $E$5, DESPESAS!$J:$J, "<>Cancelada") | F44: =SUMIFS(DESPESAS!$H:$H, DESPESAS!$E:$E, "11.7 Custo da Venda de Bens e Direitos do Ativo Não Circulante", DESPESAS!$L:$L, 3, DESPESAS!$M:$M, $E$5, DESPESAS!$J:$J, "<>Cancelada") | G44: =SUMIFS(DESPESAS!$H:$H, DESPESAS!$E:$E, "11.7 Custo da Venda de Bens e Direitos do Ativo Não Circulante", DESPESAS!$L:$L, 4, DESPESAS!$M:$M, $E$5, DESPESAS!$J:$J, "<>Cancelada") | H44: =SUMIFS(DESPESAS!$H:$H, DESPESAS!$E:$E, "11.7 Custo da Venda de Bens e Direitos do Ativo Não Circulante", DESPESAS!$L:$L, 5, DESPESAS!$M:$M, $E$5, DESPESAS!$J:$J, "<>Cancelada") | I44: =SUMIFS(DESPESAS!$H:$H, DESPESAS!$E:$E, "11.7 Custo da Venda de Bens e Direitos do Ativo Não Circulante", DESPESAS!$L:$L, 6, DESPESAS!$M:$M, $E$5, DESPESAS!$J:$J, "<>Cancelada") | J44: =SUMIFS(DESPESAS!$H:$H, DESPESAS!$E:$E, "11.7 Custo da Venda de Bens e Direitos do Ativo Não Circulante", DESPESAS!$L:$L, 7, DESPESAS!$M:$M, $E$5, DESPESAS!$J:$J, "<>Cancelada") | K44: =SUMIFS(DESPESAS!$H:$H, DESPESAS!$E:$E, "11.7 Custo da Venda de Bens e Direitos do Ativo Não Circulante", DESPESAS!$L:$L, 8, DESPESAS!$M:$M, $E$5, DESPESAS!$J:$J, "<>Cancelada") | L44: =SUMIFS(DESPESAS!$H:$H, DESPESAS!$E:$E, "11.7 Custo da Venda de Bens e Direitos do Ativo Não Circulante", DESPESAS!$L:$L, 9, DESPESAS!$M:$M, $E$5, DESPESAS!$J:$J, "<>Cancelada") | M44: =SUMIFS(DESPESAS!$H:$H, DESPESAS!$E:$E, "11.7 Custo da Venda de Bens e Direitos do Ativo Não Circulante", DESPESAS!$L:$L, 10, DESPESAS!$M:$M, $E$5, DESPESAS!$J:$J, "<>Cancelada") | N44: =SUMIFS(DESPESAS!$H:$H, DESPESAS!$E:$E, "11.7 Custo da Venda de Bens e Direitos do Ativo Não Circulante", DESPESAS!$L:$L, 11, DESPESAS!$M:$M, $E$5, DESPESAS!$J:$J, "<>Cancelada") | O44: =SUMIFS(DESPESAS!$H:$H, DESPESAS!$E:$E, "11.7 Custo da Venda de Bens e Direitos do Ativo Não Circulante", DESPESAS!$L:$L, 12, DESPESAS!$M:$M, $E$5, DESPESAS!$J:$J, "<>Cancelada") | P44: =SUM(D44:O44) | Q44: =IFERROR(P44/$P$19, 0)
B45: 12 | C45: RESULTADO OPERACIONAL ANTES DO IR/CSLL (5-6+9+10-11) | D45: =D23-D24+D33+D34-D37 | E45: =E23-E24+E33+E34-E37 | F45: =F23-F24+F33+F34-F37 | G45: =G23-G24+G33+G34-G37 | H45: =H23-H24+H33+H34-H37 | I45: =I23-I24+I33+I34-I37 | J45: =J23-J24+J33+J34-J37 | K45: =K23-K24+K33+K34-K37 | ... O45: =O23-O24+O33+O34-O37 | P45: =SUM(D45:O45) | Q45: =IFERROR(P45/$P$19, 0)
B46: 13 | C46: Provisão para IR e CSLL | D46: =SUM(D47:D48) | E46: =SUM(E47:E48) | F46: =SUM(F47:F48) | G46: =SUM(G47:G48) | H46: =SUM(H47:H48) | I46: =SUM(I47:I48) | J46: =SUM(J47:J48) | K46: =SUM(K47:K48) | ... O46: =SUM(O47:O48) | P46: =SUM(D46:O46) | Q46: =IFERROR(P46/$P$19, 0)
...

Sheet FLUXO_CAIXA
B2: 💰 DEMONSTRATIVO DE FLUXO DE CAIXA E RESULTADOS (ENTRADAS VS SAÍDAS)
B5: EMPRESA: | C5: =CONFIG!B2 | D5: ANO: | E5: 2026
B7: 🟢 TOTAL ENTRADAS (ANO) | D7: 🔴 TOTAL SAÍDAS PAGAS | G7: 💰 RESULTADO CAIXA (ANO) | J7: ⏳ DESPESAS PENDENTES (A PAGAR) | N7: 📊 COMPROMETIMENTO CAIXA (%)
B8: =P17 | D8: =P39 | G8: =P41 | J8: =SUMIFS(DESPESAS!H:H, DESPESAS!J:J, "Pendente", DESPESAS!M:M, E5) | N8: =IFERROR(P39/P17,0)
B11: ITEM | C11: ENTRADAS (RECEITAS) | D11: JAN | E11: FEV | F11: MAR | G11: ABR | H11: MAI | I11: JUN | J11: JUL | K11: AGO | L11: SET | M11: OUT | N11: NOV | O11: DEZ | P11: TOTAL ANUAL
B12: 1.1 | C12: Vendas de produtos (com nota fiscal / PDV) | D12: =MAX(0, APURACAO_RESULTADOS!D13 - APURACAO_RESULTADOS!D18) | E12: =MAX(0, APURACAO_RESULTADOS!E13 - APURACAO_RESULTADOS!E18) | F12: =MAX(0, APURACAO_RESULTADOS!F13 - APURACAO_RESULTADOS!F18) | G12: =MAX(0, APURACAO_RESULTADOS!G13 - APURACAO_RESULTADOS!G18) | H12: =MAX(0, APURACAO_RESULTADOS!H13 - APURACAO_RESULTADOS!H18) | I12: =MAX(0, APURACAO_RESULTADOS!I13 - APURACAO_RESULTADOS!I18) | J12: =MAX(0, APURACAO_RESULTADOS!J13 - APURACAO_RESULTADOS!J18) | K12: =MAX(0, APURACAO_RESULTADOS!K13 - APURACAO_RESULTADOS!K18) | ... O12: =MAX(0, APURACAO_RESULTADOS!O13 - APURACAO_RESULTADOS!O18) | P12: =SUM(D12:O12)
B13: 1.2 | C13: Vendas de produtos (sem nota fiscal)* | D13: 0 | E13: 0 | F13: 0 | G13: 0 | H13: 0 | I13: 0 | J13: 0 | K13: 0 | L13: 0 | M13: 0 | N13: 0 | O13: 0 | P13: =SUM(D13:O13)
B14: 1.3 | C14: Prestação de serviços (com nota fiscal / PDV) | D14: =APURACAO_RESULTADOS!D14 | E14: =APURACAO_RESULTADOS!E14 | F14: =APURACAO_RESULTADOS!F14 | G14: =APURACAO_RESULTADOS!G14 | H14: =APURACAO_RESULTADOS!H14 | I14: =APURACAO_RESULTADOS!I14 | J14: =APURACAO_RESULTADOS!J14 | K14: =APURACAO_RESULTADOS!K14 | ... O14: =APURACAO_RESULTADOS!O14 | P14: =SUM(D14:O14)
B15: 1.4 | C15: Prestação de serviços (sem nota fiscal)* | D15: 0 | E15: 0 | F15: 0 | G15: 0 | H15: 0 | I15: 0 | J15: 0 | K15: 0 | L15: 0 | M15: 0 | N15: 0 | O15: 0 | P15: =SUM(D15:O15)
B16: 1.5 | C16: Outras receitas (aplicações no banco, etc.) | D16: =APURACAO_RESULTADOS!D27 + APURACAO_RESULTADOS!D34 | E16: =APURACAO_RESULTADOS!E27 + APURACAO_RESULTADOS!E34 | F16: =APURACAO_RESULTADOS!F27 + APURACAO_RESULTADOS!F34 | G16: =APURACAO_RESULTADOS!G27 + APURACAO_RESULTADOS!G34 | H16: =APURACAO_RESULTADOS!H27 + APURACAO_RESULTADOS!H34 | I16: =APURACAO_RESULTADOS!I27 + APURACAO_RESULTADOS!I34 | J16: =APURACAO_RESULTADOS!J27 + APURACAO_RESULTADOS!J34 | K16: =APURACAO_RESULTADOS!K27 + APURACAO_RESULTADOS!K34 | ... O16: =APURACAO_RESULTADOS!O27 + APURACAO_RESULTADOS!O34 | P16: =SUM(D16:O16)
B17: 1 | C17: TOTAL DE ENTRADAS | D17: =SUM(D12:D16) | E17: =SUM(E12:E16) | F17: =SUM(F12:F16) | G17: =SUM(G12:G16) | H17: =SUM(H12:H16) | I17: =SUM(I12:I16) | J17: =SUM(J12:J16) | K17: =SUM(K12:K16) | ... P17: =SUM(P12:P16)
B19: ITEM | C19: SAÍDAS (GASTOS) | D19: JAN | E19: FEV | F19: MAR | G19: ABR | H19: MAI | I19: JUN | J19: JUL | K19: AGO | L19: SET | M19: OUT | N19: NOV | O19: DEZ | P19: TOTAL ANUAL
B20: 2.1 | C20: Retirada do(s) proprietário(s) ** | D20: =SUMIFS(DESPESAS!$H:$H, DESPESAS!$F:$F, "Retirada do(s) proprietário(s)", DESPESAS!$N:$N, 1, DESPESAS!$O:$O, $E$5, DESPESAS!$J:$J, "Paga") | E20: =SUMIFS(DESPESAS!$H:$H, DESPESAS!$F:$F, "Retirada do(s) proprietário(s)", DESPESAS!$N:$N, 2, DESPESAS!$O:$O, $E$5, DESPESAS!$J:$J, "Paga") | F20: =SUMIFS(DESPESAS!$H:$H, DESPESAS!$F:$F, "Retirada do(s) proprietário(s)", DESPESAS!$N:$N, 3, DESPESAS!$O:$O, $E$5, DESPESAS!$J:$J, "Paga") | G20: =SUMIFS(DESPESAS!$H:$H, DESPESAS!$F:$F, "Retirada do(s) proprietário(s)", DESPESAS!$N:$N, 4, DESPESAS!$O:$O, $E$5, DESPESAS!$J:$J, "Paga") | H20: =SUMIFS(DESPESAS!$H:$H, DESPESAS!$F:$F, "Retirada do(s) proprietário(s)", DESPESAS!$N:$N, 5, DESPESAS!$O:$O, $E$5, DESPESAS!$J:$J, "Paga") | I20: =SUMIFS(DESPESAS!$H:$H, DESPESAS!$F:$F, "Retirada do(s) proprietário(s)", DESPESAS!$N:$N, 6, DESPESAS!$O:$O, $E$5, DESPESAS!$J:$J, "Paga") | J20: =SUMIFS(DESPESAS!$H:$H, DESPESAS!$F:$F, "Retirada do(s) proprietário(s)", DESPESAS!$N:$N, 7, DESPESAS!$O:$O, $E$5, DESPESAS!$J:$J, "Paga") | K20: =SUMIFS(DESPESAS!$H:$H, DESPESAS!$F:$F, "Retirada do(s) proprietário(s)", DESPESAS!$N:$N, 8, DESPESAS!$O:$O, $E$5, DESPESAS!$J:$J, "Paga") | L20: =SUMIFS(DESPESAS!$H:$H, DESPESAS!$F:$F, "Retirada do(s) proprietário(s)", DESPESAS!$N:$N, 9, DESPESAS!$O:$O, $E$5, DESPESAS!$J:$J, "Paga") | M20: =SUMIFS(DESPESAS!$H:$H, DESPESAS!$F:$F, "Retirada do(s) proprietário(s)", DESPESAS!$N:$N, 10, DESPESAS!$O:$O, $E$5, DESPESAS!$J:$J, "Paga") | N20: =SUMIFS(DESPESAS!$H:$H, DESPESAS!$F:$F, "Retirada do(s) proprietário(s)", DESPESAS!$N:$N, 11, DESPESAS!$O:$O, $E$5, DESPESAS!$J:$J, "Paga") | O20: =SUMIFS(DESPESAS!$H:$H, DESPESAS!$F:$F, "Retirada do(s) proprietário(s)", DESPESAS!$N:$N, 12, DESPESAS!$O:$O, $E$5, DESPESAS!$J:$J, "Paga") | P20: =SUM(D20:O20)
B21: 2.2 | C21: Gastos com produtos para venda | D21: =SUMIFS(DESPESAS!$H:$H, DESPESAS!$F:$F, "Gastos com produtos para venda", DESPESAS!$N:$N, 1, DESPESAS!$O:$O, $E$5, DESPESAS!$J:$J, "Paga") | E21: =SUMIFS(DESPESAS!$H:$H, DESPESAS!$F:$F, "Gastos com produtos para venda", DESPESAS!$N:$N, 2, DESPESAS!$O:$O, $E$5, DESPESAS!$J:$J, "Paga") | F21: =SUMIFS(DESPESAS!$H:$H, DESPESAS!$F:$F, "Gastos com produtos para venda", DESPESAS!$N:$N, 3, DESPESAS!$O:$O, $E$5, DESPESAS!$J:$J, "Paga") | G21: =SUMIFS(DESPESAS!$H:$H, DESPESAS!$F:$F, "Gastos com produtos para venda", DESPESAS!$N:$N, 4, DESPESAS!$O:$O, $E$5, DESPESAS!$J:$J, "Paga") | H21: =SUMIFS(DESPESAS!$H:$H, DESPESAS!$F:$F, "Gastos com produtos para venda", DESPESAS!$N:$N, 5, DESPESAS!$O:$O, $E$5, DESPESAS!$J:$J, "Paga") | I21: =SUMIFS(DESPESAS!$H:$H, DESPESAS!$F:$F, "Gastos com produtos para venda", DESPESAS!$N:$N, 6, DESPESAS!$O:$O, $E$5, DESPESAS!$J:$J, "Paga") | J21: =SUMIFS(DESPESAS!$H:$H, DESPESAS!$F:$F, "Gastos com produtos para venda", DESPESAS!$N:$N, 7, DESPESAS!$O:$O, $E$5, DESPESAS!$J:$J, "Paga") | K21: =SUMIFS(DESPESAS!$H:$H, DESPESAS!$F:$F, "Gastos com produtos para venda", DESPESAS!$N:$N, 8, DESPESAS!$O:$O, $E$5, DESPESAS!$J:$J, "Paga") | L21: =SUMIFS(DESPESAS!$H:$H, DESPESAS!$F:$F, "Gastos com produtos para venda", DESPESAS!$N:$N, 9, DESPESAS!$O:$O, $E$5, DESPESAS!$J:$J, "Paga") | M21: =SUMIFS(DESPESAS!$H:$H, DESPESAS!$F:$F, "Gastos com produtos para venda", DESPESAS!$N:$N, 10, DESPESAS!$O:$O, $E$5, DESPESAS!$J:$J, "Paga") | N21: =SUMIFS(DESPESAS!$H:$H, DESPESAS!$F:$F, "Gastos com produtos para venda", DESPESAS!$N:$N, 11, DESPESAS!$O:$O, $E$5, DESPESAS!$J:$J, "Paga") | O21: =SUMIFS(DESPESAS!$H:$H, DESPESAS!$F:$F, "Gastos com produtos para venda", DESPESAS!$N:$N, 12, DESPESAS!$O:$O, $E$5, DESPESAS!$J:$J, "Paga") | P21: =SUM(D21:O21)
B22: 2.3 | C22: Gastos com serviços prestados *** | D22: =SUMIFS(DESPESAS!$H:$H, DESPESAS!$F:$F, "Gastos com serviços prestados", DESPESAS!$N:$N, 1, DESPESAS!$O:$O, $E$5, DESPESAS!$J:$J, "Paga") | E22: =SUMIFS(DESPESAS!$H:$H, DESPESAS!$F:$F, "Gastos com serviços prestados", DESPESAS!$N:$N, 2, DESPESAS!$O:$O, $E$5, DESPESAS!$J:$J, "Paga") | F22: =SUMIFS(DESPESAS!$H:$H, DESPESAS!$F:$F, "Gastos com serviços prestados", DESPESAS!$N:$N, 3, DESPESAS!$O:$O, $E$5, DESPESAS!$J:$J, "Paga") | G22: =SUMIFS(DESPESAS!$H:$H, DESPESAS!$F:$F, "Gastos com serviços prestados", DESPESAS!$N:$N, 4, DESPESAS!$O:$O, $E$5, DESPESAS!$J:$J, "Paga") | H22: =SUMIFS(DESPESAS!$H:$H, DESPESAS!$F:$F, "Gastos com serviços prestados", DESPESAS!$N:$N, 5, DESPESAS!$O:$O, $E$5, DESPESAS!$J:$J, "Paga") | I22: =SUMIFS(DESPESAS!$H:$H, DESPESAS!$F:$F, "Gastos com serviços prestados", DESPESAS!$N:$N, 6, DESPESAS!$O:$O, $E$5, DESPESAS!$J:$J, "Paga") | J22: =SUMIFS(DESPESAS!$H:$H, DESPESAS!$F:$F, "Gastos com serviços prestados", DESPESAS!$N:$N, 7, DESPESAS!$O:$O, $E$5, DESPESAS!$J:$J, "Paga") | K22: =SUMIFS(DESPESAS!$H:$H, DESPESAS!$F:$F, "Gastos com serviços prestados", DESPESAS!$N:$N, 8, DESPESAS!$O:$O, $E$5, DESPESAS!$J:$J, "Paga") | L22: =SUMIFS(DESPESAS!$H:$H, DESPESAS!$F:$F, "Gastos com serviços prestados", DESPESAS!$N:$N, 9, DESPESAS!$O:$O, $E$5, DESPESAS!$J:$J, "Paga") | M22: =SUMIFS(DESPESAS!$H:$H, DESPESAS!$F:$F, "Gastos com serviços prestados", DESPESAS!$N:$N, 10, DESPESAS!$O:$O, $E$5, DESPESAS!$J:$J, "Paga") | N22: =SUMIFS(DESPESAS!$H:$H, DESPESAS!$F:$F, "Gastos com serviços prestados", DESPESAS!$N:$N, 11, DESPESAS!$O:$O, $E$5, DESPESAS!$J:$J, "Paga") | O22: =SUMIFS(DESPESAS!$H:$H, DESPESAS!$F:$F, "Gastos com serviços prestados", DESPESAS!$N:$N, 12, DESPESAS!$O:$O, $E$5, DESPESAS!$J:$J, "Paga") | P22: =SUM(D22:O22)
B23: 2.4 | C23: Carnê de arrecadação - MEI | D23: =SUMIFS(DESPESAS!$H:$H, DESPESAS!$F:$F, "Carnê de arrecadação - MEI", DESPESAS!$N:$N, 1, DESPESAS!$O:$O, $E$5, DESPESAS!$J:$J, "Paga") | E23: =SUMIFS(DESPESAS!$H:$H, DESPESAS!$F:$F, "Carnê de arrecadação - MEI", DESPESAS!$N:$N, 2, DESPESAS!$O:$O, $E$5, DESPESAS!$J:$J, "Paga") | F23: =SUMIFS(DESPESAS!$H:$H, DESPESAS!$F:$F, "Carnê de arrecadação - MEI", DESPESAS!$N:$N, 3, DESPESAS!$O:$O, $E$5, DESPESAS!$J:$J, "Paga") | G23: =SUMIFS(DESPESAS!$H:$H, DESPESAS!$F:$F, "Carnê de arrecadação - MEI", DESPESAS!$N:$N, 4, DESPESAS!$O:$O, $E$5, DESPESAS!$J:$J, "Paga") | H23: =SUMIFS(DESPESAS!$H:$H, DESPESAS!$F:$F, "Carnê de arrecadação - MEI", DESPESAS!$N:$N, 5, DESPESAS!$O:$O, $E$5, DESPESAS!$J:$J, "Paga") | I23: =SUMIFS(DESPESAS!$H:$H, DESPESAS!$F:$F, "Carnê de arrecadação - MEI", DESPESAS!$N:$N, 6, DESPESAS!$O:$O, $E$5, DESPESAS!$J:$J, "Paga") | J23: =SUMIFS(DESPESAS!$H:$H, DESPESAS!$F:$F, "Carnê de arrecadação - MEI", DESPESAS!$N:$N, 7, DESPESAS!$O:$O, $E$5, DESPESAS!$J:$J, "Paga") | K23: =SUMIFS(DESPESAS!$H:$H, DESPESAS!$F:$F, "Carnê de arrecadação - MEI", DESPESAS!$N:$N, 8, DESPESAS!$O:$O, $E$5, DESPESAS!$J:$J, "Paga") | L23: =SUMIFS(DESPESAS!$H:$H, DESPESAS!$F:$F, "Carnê de arrecadação - MEI", DESPESAS!$N:$N, 9, DESPESAS!$O:$O, $E$5, DESPESAS!$J:$J, "Paga") | M23: =SUMIFS(DESPESAS!$H:$H, DESPESAS!$F:$F, "Carnê de arrecadação - MEI", DESPESAS!$N:$N, 10, DESPESAS!$O:$O, $E$5, DESPESAS!$J:$J, "Paga") | N23: =SUMIFS(DESPESAS!$H:$H, DESPESAS!$F:$F, "Carnê de arrecadação - MEI", DESPESAS!$N:$N, 11, DESPESAS!$O:$O, $E$5, DESPESAS!$J:$J, "Paga") | O23: =SUMIFS(DESPESAS!$H:$H, DESPESAS!$F:$F, "Carnê de arrecadação - MEI", DESPESAS!$N:$N, 12, DESPESAS!$O:$O, $E$5, DESPESAS!$J:$J, "Paga") | P23: =SUM(D23:O23)
B24: 2.5 | C24: DAS - Documento de Arrecadação Simples | D24: =SUMIFS(DESPESAS!$H:$H, DESPESAS!$F:$F, "DAS - Documento de Arrecadação Simples", DESPESAS!$N:$N, 1, DESPESAS!$O:$O, $E$5, DESPESAS!$J:$J, "Paga") | E24: =SUMIFS(DESPESAS!$H:$H, DESPESAS!$F:$F, "DAS - Documento de Arrecadação Simples", DESPESAS!$N:$N, 2, DESPESAS!$O:$O, $E$5, DESPESAS!$J:$J, "Paga") | F24: =SUMIFS(DESPESAS!$H:$H, DESPESAS!$F:$F, "DAS - Documento de Arrecadação Simples", DESPESAS!$N:$N, 3, DESPESAS!$O:$O, $E$5, DESPESAS!$J:$J, "Paga") | G24: =SUMIFS(DESPESAS!$H:$H, DESPESAS!$F:$F, "DAS - Documento de Arrecadação Simples", DESPESAS!$N:$N, 4, DESPESAS!$O:$O, $E$5, DESPESAS!$J:$J, "Paga") | H24: =SUMIFS(DESPESAS!$H:$H, DESPESAS!$F:$F, "DAS - Documento de Arrecadação Simples", DESPESAS!$N:$N, 5, DESPESAS!$O:$O, $E$5, DESPESAS!$J:$J, "Paga") | I24: =SUMIFS(DESPESAS!$H:$H, DESPESAS!$F:$F, "DAS - Documento de Arrecadação Simples", DESPESAS!$N:$N, 6, DESPESAS!$O:$O, $E$5, DESPESAS!$J:$J, "Paga") | J24: =SUMIFS(DESPESAS!$H:$H, DESPESAS!$F:$F, "DAS - Documento de Arrecadação Simples", DESPESAS!$N:$N, 7, DESPESAS!$O:$O, $E$5, DESPESAS!$J:$J, "Paga") | K24: =SUMIFS(DESPESAS!$H:$H, DESPESAS!$F:$F, "DAS - Documento de Arrecadação Simples", DESPESAS!$N:$N, 8, DESPESAS!$O:$O, $E$5, DESPESAS!$J:$J, "Paga") | L24: =SUMIFS(DESPESAS!$H:$H, DESPESAS!$F:$F, "DAS - Documento de Arrecadação Simples", DESPESAS!$N:$N, 9, DESPESAS!$O:$O, $E$5, DESPESAS!$J:$J, "Paga") | M24: =SUMIFS(DESPESAS!$H:$H, DESPESAS!$F:$F, "DAS - Documento de Arrecadação Simples", DESPESAS!$N:$N, 10, DESPESAS!$O:$O, $E$5, DESPESAS!$J:$J, "Paga") | N24: =SUMIFS(DESPESAS!$H:$H, DESPESAS!$F:$F, "DAS - Documento de Arrecadação Simples", DESPESAS!$N:$N, 11, DESPESAS!$O:$O, $E$5, DESPESAS!$J:$J, "Paga") | O24: =SUMIFS(DESPESAS!$H:$H, DESPESAS!$F:$F, "DAS - Documento de Arrecadação Simples", DESPESAS!$N:$N, 12, DESPESAS!$O:$O, $E$5, DESPESAS!$J:$J, "Paga") | P24: =SUM(D24:O24)
B25: 2.6 | C25: Folha de pagamento | D25: 0 | E25: =SUMIFS(DESPESAS!$H:$H, DESPESAS!$F:$F, "Folha de pagamento", DESPESAS!$N:$N, 2, DESPESAS!$O:$O, $E$5, DESPESAS!$J:$J, "Paga") | F25: =SUMIFS(DESPESAS!$H:$H, DESPESAS!$F:$F, "Folha de pagamento", DESPESAS!$N:$N, 3, DESPESAS!$O:$O, $E$5, DESPESAS!$J:$J, "Paga") | G25: =SUMIFS(DESPESAS!$H:$H, DESPESAS!$F:$F, "Folha de pagamento", DESPESAS!$N:$N, 4, DESPESAS!$O:$O, $E$5, DESPESAS!$J:$J, "Paga") | H25: =SUMIFS(DESPESAS!$H:$H, DESPESAS!$F:$F, "Folha de pagamento", DESPESAS!$N:$N, 5, DESPESAS!$O:$O, $E$5, DESPESAS!$J:$J, "Paga") | I25: =SUMIFS(DESPESAS!$H:$H, DESPESAS!$F:$F, "Folha de pagamento", DESPESAS!$N:$N, 6, DESPESAS!$O:$O, $E$5, DESPESAS!$J:$J, "Paga") | J25: =SUMIFS(DESPESAS!$H:$H, DESPESAS!$F:$F, "Folha de pagamento", DESPESAS!$N:$N, 7, DESPESAS!$O:$O, $E$5, DESPESAS!$J:$J, "Paga") | K25: =SUMIFS(DESPESAS!$H:$H, DESPESAS!$F:$F, "Folha de pagamento", DESPESAS!$N:$N, 8, DESPESAS!$O:$O, $E$5, DESPESAS!$J:$J, "Paga") | L25: =SUMIFS(DESPESAS!$H:$H, DESPESAS!$F:$F, "Folha de pagamento", DESPESAS!$N:$N, 9, DESPESAS!$O:$O, $E$5, DESPESAS!$J:$J, "Paga") | M25: =SUMIFS(DESPESAS!$H:$H, DESPESAS!$F:$F, "Folha de pagamento", DESPESAS!$N:$N, 10, DESPESAS!$O:$O, $E$5, DESPESAS!$J:$J, "Paga") | N25: =SUMIFS(DESPESAS!$H:$H, DESPESAS!$F:$F, "Folha de pagamento", DESPESAS!$N:$N, 11, DESPESAS!$O:$O, $E$5, DESPESAS!$J:$J, "Paga") | O25: =SUMIFS(DESPESAS!$H:$H, DESPESAS!$F:$F, "Folha de pagamento", DESPESAS!$N:$N, 12, DESPESAS!$O:$O, $E$5, DESPESAS!$J:$J, "Paga") | P25: =SUM(D25:O25)
B26: 2.7 | C26: Outros tributos (impostos, taxas, etc.) | D26: 0 | E26: =SUMIFS(DESPESAS!$H:$H, DESPESAS!$F:$F, "Outros tributos (impostos, taxas, etc.)", DESPESAS!$N:$N, 2, DESPESAS!$O:$O, $E$5, DESPESAS!$J:$J, "Paga") | F26: =SUMIFS(DESPESAS!$H:$H, DESPESAS!$F:$F, "Outros tributos (impostos, taxas, etc.)", DESPESAS!$N:$N, 3, DESPESAS!$O:$O, $E$5, DESPESAS!$J:$J, "Paga") | G26: =SUMIFS(DESPESAS!$H:$H, DESPESAS!$F:$F, "Outros tributos (impostos, taxas, etc.)", DESPESAS!$N:$N, 4, DESPESAS!$O:$O, $E$5, DESPESAS!$J:$J, "Paga") | H26: =SUMIFS(DESPESAS!$H:$H, DESPESAS!$F:$F, "Outros tributos (impostos, taxas, etc.)", DESPESAS!$N:$N, 5, DESPESAS!$O:$O, $E$5, DESPESAS!$J:$J, "Paga") | I26: =SUMIFS(DESPESAS!$H:$H, DESPESAS!$F:$F, "Outros tributos (impostos, taxas, etc.)", DESPESAS!$N:$N, 6, DESPESAS!$O:$O, $E$5, DESPESAS!$J:$J, "Paga") | J26: =SUMIFS(DESPESAS!$H:$H, DESPESAS!$F:$F, "Outros tributos (impostos, taxas, etc.)", DESPESAS!$N:$N, 7, DESPESAS!$O:$O, $E$5, DESPESAS!$J:$J, "Paga") | K26: =SUMIFS(DESPESAS!$H:$H, DESPESAS!$F:$F, "Outros tributos (impostos, taxas, etc.)", DESPESAS!$N:$N, 8, DESPESAS!$O:$O, $E$5, DESPESAS!$J:$J, "Paga") | L26: =SUMIFS(DESPESAS!$H:$H, DESPESAS!$F:$F, "Outros tributos (impostos, taxas, etc.)", DESPESAS!$N:$N, 9, DESPESAS!$O:$O, $E$5, DESPESAS!$J:$J, "Paga") | M26: =SUMIFS(DESPESAS!$H:$H, DESPESAS!$F:$F, "Outros tributos (impostos, taxas, etc.)", DESPESAS!$N:$N, 10, DESPESAS!$O:$O, $E$5, DESPESAS!$J:$J, "Paga") | N26: =SUMIFS(DESPESAS!$H:$H, DESPESAS!$F:$F, "Outros tributos (impostos, taxas, etc.)", DESPESAS!$N:$N, 11, DESPESAS!$O:$O, $E$5, DESPESAS!$J:$J, "Paga") | O26: =SUMIFS(DESPESAS!$H:$H, DESPESAS!$F:$F, "Outros tributos (impostos, taxas, etc.)", DESPESAS!$N:$N, 12, DESPESAS!$O:$O, $E$5, DESPESAS!$J:$J, "Paga") | P26: =SUM(D26:O26)
